Workbook
Name OLE_LINK2: 'LAMP.10 (II)'!#REF!
Name OLE_LINK2: 'LAMP.11 (I)'!#REF!
Name OLE_LINK2: 'LAMP.11 (II)'!#REF!
Name OLE_LINK2: LAMP.16!#REF!
Name OLE_LINK2: 'LAMP.8 (I)'!#REF!
Name OLE_LINK2: 'LAMP.8 (II)'!#REF!
Name OLE_LINK3: 'LAMP.10 (II)'!#REF!
Name OLE_LINK3: 'LAMP.11 (I)'!#REF!
Name OLE_LINK3: 'LAMP.11 (II)'!#REF!
Name OLE_LINK3: LAMP.16!#REF!
Name OLE_LINK3: 'LAMP.8 (I)'!#REF!
Name OLE_LINK3: 'LAMP.8 (II)'!#REF!

Sheet Sheet4

Sheet LAMP.8 (I)
M1: LAMPIRAN 8
A2: BUKU PENERIMAAN BARANG
A5: No | B5: Tanggal | C5: Dari | D5: Dokumen Faktur | F5: Nama Barang | G5: Banyaknya | I5: Harga Satuan (Rp.) | J5: Jumlah Harga (Rp.) | K5: Bukti Penerimaan/ | M5: Keterangan
K6: B.A. Penerimaan
D7: Nomor | E7: Tanggal | K7: Nomor | L7: Tanggal
A8: 1 | B8: 2 | C8: 3 | D8: 4 | E8: 5 | F8: 6 | G8: 7 | I8: 8 | J8: 9 | K8: 10 | L8: 11 | M8: 12
A10: 1. Alat Tulis Kantor
B13: 46062 | C13: CV "Centrojaya" | F13: Dokumen keeper resleting | G13: 4 | H13: buah | I13: 65490 | J13: =I13*G13 -> 261960 | K13: 000.3/20.3-1/104/2026 | L13: 46072 | O13: =SUM(J13) -> 261960 | P13: Belnja kegiatan kantor
B16: 46062 | C16: CV "Centrojaya" | F16: Pensil 2B steadtler | G16: 9 | H16: buah | I16: 4440 | J16: =I16*G16 -> 39960 | K16: 000.3/27.2-1/104/2026 | L16: 46072
F17: Stabilo Artline | G17: 3 | H17: buah | I17: 8880 | J17: =G17*I17 -> 26640
F18: Map portepel | G18: 18 | H18: buah | I18: 7770 | J18: =G18*I18 -> 139860
F19: Bolpen Weiyada | G19: 36 | H19: buah | I19: 4995 | J19: =I19*G19 -> 179820
F20: Corection tape | G20: 8 | H20: buah | I20: 13320 | J20: =I20*G20 -> 106560 | O20: =SUM(J16:J20) -> 492840 | P20: Belnja kegiatan kantor
B22: 46072 | C22: CV "Centrojaya" | F22: Map plastik | G22: 26 | H22: buah | I22: 5550 | J22: =I22*G22 -> 144300 | K22: 000.3/27.3-1/104/2026 | L22: 46072
F23: Block Note | G23: 26 | H23: buah | I23: 6105 | J23: =G23*I23 -> 158730
F24: Bolpen Snowman V7 | G24: 26 | H24: buah | I24: 3330 | J24: =I24*G24 -> 86580 | O24: =SUM(J22:J24) -> 389610 | P24: Belnja kegiatan kantor
B27: 46090 | C27: CV "Centrojaya" | F27: Map Portepel | G27: 31 | H27: buah | I27: 7770 | J27: =I27*G27 -> 240870 | K27: 000.3/45.3-1/104/2026 | L27: 46090 | O27: =SUM(J27) -> 240870 | P27: Belnja kegiatan kantor
A71: 2. Bahan Komputer
B74: 46059 | C74: CV " Centrojaya" | F74: Tinta printer Epson-003 | G74: 7 | H74: botol | I74: 115000.4 | J74: =G74*I74 -> 805002.8 | K74: 003.2/23.2-1/104/2026 | L74: 46059 | O74: =SUM(J74:J75) -> 805002.8 | P74: Belanja alat bahan kegiatan kantor
B76: 46065 | C76: CV " Centrojaya" | F76: Tinta printer Epson-003 | G76: 5 | H76: botol | I76: 114330 | J76: =G76*I76 -> 571650 | K76: 003.2/23.3-1/104/2026 | L76: 46065 | O76: =SUM(J76) -> 571650 | P76: Belanja alat bahan kegiatan kantor
B78: 46073 | C78: CV " Centrojaya" | F78: Tinta printer Epson-003 | G78: 2 | H78: botol | I78: 114330 | J78: =G78*I78 -> 228660 | K78: 003.2/47.2-1/104/2026 | L78: 46090 | O78: =SUM(J78:J79) -> 378510 | P78: Belanja alat bahan kegiatan kantor
F79: Flas dis OTG 16 | G79: 1 | H79: botol | I79: 149850 | J79: =G79*I79 -> 149850
B81: 46090 | C81: CV " Centrojaya" | F81: Tinta printer Epson-003 | G81: 10 | H81: botol | I81: 114330 | J81: =G81*I81 -> 1143300 | K81: 003.2/47.2-1/104/2026 | L81: 46090 | O81: =SUM(J81:J82) -> 1143300 | P81: Belanja alat bahan kegiatan kantor
B86: 46077 | C86: CV " Centrojaya" | F86: Tinta Epson 664 Warna | G86: 3 | H86: botol | I86: 114000 | J86: =G86*I86 -> 342000 | K86: 003.2/26.2-1/104/2026 | L86: 45712
F87: Tinta Epson 664 hitam | G87: 9 | H87: botol | I87: 114000 | J87: =G87*I87 -> 1026000 | O87: =SUM(J86:J87) -> 1368000 | P87: Bahan Komputer
A92: 3. Kertas dan Cover
B95: 46050 | C95: CV " Centrojaya" | F95: Kertas HVS SIDU F4 | G95: 4 | H95: rim | I95: 58830 | J95: =G95*I95 -> 235320 | K95: 003.2/21.2-1/104/2026 | L95: 46050 | O95: =SUM(J95:J96) -> 801420 | P95: Belanja alat bahan kegiatan kantor
F96: Kertas HVS SIDU A4 | G96: 10 | H96: rim | I96: 56610 | J96: =G96*I96 -> 566100
B98: 46062 | C98: CV " Centrojaya" | F98: Kertas HVS SIDU A4 | G98: 5 | H98: rim | I98: 56610 | J98: =G98*I98 -> 283050 | K98: 003.2/21.3-1/104/2026 | L98: 46062 | O98: =SUM(J98) -> 283050 | P98: Belanja alat bahan kegiatan kantor
B100: 46081 | C100: CV " Centrojaya" | F100: Kertas HVS SIDU F4 | G100: 3 | H100: rim | I100: 58941 | J100: =G100*I100 -> 176823 | K100: 003.2/25.2-1/104/2026 | L100: 46081
F101: Kertas HVS SIDU A4 | G101: 9 | H101: rim | I101: 55500 | J101: =G101*I101 -> 499500
F102: NCR A4 | G102: 3 | H102: rim | I102: 79920 | J102: =G102*I102 -> 239760 | O102: =SUM(J100:J102) -> 916083 | P102: Belanja alat bahan kegiatan kantor rsn
B106: 46093 | C106: CV " Centrojaya" | F106: Kertas HVS SIDU A4 | G106: 38 | H106: rim | I106: 56610 | J106: =G106*I106 -> 2151180 | K106: 003.2/300.2-1/104/2026 | L106: 46093
F107: Kertas HVS SIDU F4 | G107: 2 | H107: rim | I107: 61050 | J107: =G107*I107 -> 122100 | O107: =SUM(J106:J107) -> 2273280 | P107: Waskim
B109: 46093 | C109: CV " Centrojaya" | F109: Kertas HVS SIDU A4 | G109: 6 | H109: rim | I109: 56610 | J109: =G109*I109 -> 339660 | K109: 003.2/309-3/104/2026 | L109: 46093 | O109: =SUM(J109) -> 339660 | P109: Perumahan
B111: 46090 | C111: CV " Centrojaya" | F111: Kertas HVS SIDU F4 | G111: 15 | H111: rim | I111: 53280 | J111: =G111*I111 -> 799200 | K111: 003.2/48.2-1/104/2026 | L111: 46090 | O111: =SUM(J111:J112) -> 799200 | P111: Belanja alat bahan kegiatan kantor
A115: 4. Alat Listrik dan Elektronik
B117: 46112 | C117: CV " Centrojaya" | F117: Lampu LED 14 Watt | G117: 40 | H117: buah | I117: 66600 | J117: =I117*G117 -> 2664000 | K117: 000.3.2/44.3-1/423.109/2025 | L117: 46112
F118: Baterai AA | G118: 28 | H118: buah | I118: 16650 | J118: =I118*G118 -> 466200
F119: Baterai AAA | G119: 20 | H119: buah | I119: 22200 | J119: =I119*G119 -> 444000
...

Sheet LAMP.9 (I)
K1: LAMPIRAN 9
A3: BUKU PENGELUARAN BARANG
A6: No. | B6: Tanggal | C6: Nomor Urut | D6: Nama Barang | E6: Banyaknya | G6: Harga Satuan | H6: Jumlah Harga | I6: Untuk | J6: Tanggal Penyerahan | K6: Ket
A8: 1 | B8: 2 | C8: 3 | D8: 4 | E8: 5 | G8: 6 | H8: 7 | I8: 8 | J8: 9 | K8: 10
A10: ='LAMP.8 (I)'!A10:M10 -> 1. Alat Tulis Kantor
J308: Pasuruan, 31 Maret 2021
C310: ATASAN LANGSUNG | J310: PENYIMPAN BARANG
C314: DYAH ERMITASARI,ST,MT | J314: MUSTOFA
C315: NIP. 19721105 199803 2 012 | J315: NIP. 19720608 200701 1 020

Sheet LAMP.11 (I)
P1: LAMPIRAN 11
B2: SKPD | C2: DINAS PERUMAHAN RAKYAT DAN KAWASAN PEMUKIMAN
B3: KAB/KOTA | C3: PASURUAN
B4: PROVINSI | C4: JAWA TIMUR
A5: BUKU BARANG PAKAI HABIS
B7: PENERIMAAN | K7: PENGELUARAN
A8: No | B8: Tanggal diterima | C8: Jenis/Nama Barang | D8: Merk/ Ukuran | E8: Tahun Pembuatan | F8: Jumlah satuan/ barang | H8: Tgl/No.Kontrak/SP/SPK/harga satuan | I8: Berita Acara Pemeriksaan | K8: Tanggal Dikeluarkan | L8: Diserahkan Kepada | M8: Jumlah satuan/ barang | O8: Tgl/No.Surat Penyerahan | P8: Keterangan
I9: Tanggal | J9: Nomor
A10: 1 | B10: 2 | C10: 3 | D10: 4 | E10: 5 | F10: 6 | H10: 7 | I10: 8 | J10: 9 | K10: 10 | L10: 11 | M10: 12 | O10: 13 | P10: 14
A12: ='LAMP.8 (I)'!A10:M10 -> 1. Alat Tulis Kantor
N306: Pasuruan, 31 Maret 2022
C308: ATASAN LANGSUNG | N308: PENGURUS BARANG
C312: DYAH ERMITASARI,ST,MT | N312: ADE CANDRA WAHYU DARMAWAN, A.Md.
C313: NIP. 19721105 199803 2 012 | N313: NIP. 199606132020121009
S333: p

Sheet LAMP 10
A1: SKPD | C1: : DINAS PERUMAHAN RAKYAT DAN KAWASAN PERMUKIMAN
A2: KOTA | C2: : PASURUAN
A3: PROVINSI | C3: : JAWA TIMUR
A4: BUKU PENERIMAAN BARANG INVENTARIS TRIBULAN I SEMESTER I TAHUN ANGGARAN 2020
A6: No | B6: Tanggal | C6: Dari | D6: Dokumen Faktur | F6: Nama Barang | G6: Banyaknya | I6: Harga Satuan | J6: Jumlah Harga | K6: Bukti Penerimaan | M6: Ket.
K7: B.A. Penerimaan
D8: Nomor | E8: Tanggal | K8: Nomor | L8: Tanggal
A9: 1 | B9: 2 | C9: 3 | D9: 4 | E9: 5 | F9: 6 | G9: 7 | I9: 8 | J9: 9 | K9: 10 | L9: 11 | M9: 12
A10: 1 | B10: 28/2/2020 | C10: CV. SOLUSI ARYA PRIMA | D10: ARI20SUB 202100034 | E10: 28/2/2020 | F10: ASUS AID Core i5 | G10: 2 | H10: unit | I10: 10300880 | J10: =I10*G10 -> 20601760 | K10: 602.21/730/423.109/2020 | L10: 28/2/2020 | M10: PC
A11: 2 | B11: 28/2/2020 | C11: CV. SOLUSI ARYA PRIMA | D11: ARI20SUB 202100034 | E11: 28/2/2020 | F11: ASUS Pro Core i7 | G11: 2 | H11: unit | I11: 14549840 | J11: =I11*G11 -> 29099680 | K11: 602.21/730/423.109/2020 | L11: 28/2/2020 | M11: Laptop
A12: 3 | B12: 28/2/2020 | C12: CV. SOLUSI ARYA PRIMA | D12: ARI20SUB 202100034 | E12: 28/2/2020 | F12: Epson Ink Jet L1110 | G12: 4 | H12: unit | I12: 2090820 | J12: =I12*G12 -> 8363280 | K12: 602.21/730/423.109/2020 | L12: 28/2/2020 | M12: Printer
A13: 4 | B13: 28/2/2020 | C13: CV. SOLUSI ARYA PRIMA | D13: ARI20SUB 202100034 | E13: 28/2/2020 | F13: Ink Jet L1300 | G13: 1 | H13: unit | I13: 6400000 | J13: =I13*G13 -> 6400000 | K13: 602.21/730/423.109/2020 | L13: 28/2/2020 | M13: Printer
A14: 5 | B14: 44077 | C14: PT. COBAS KARAYA NUSANTARA | D14: 101/PP/CBS/III/2020 | E14: 44077 | F14: Denko Alumunium Single | G14: 4 | H14: unit | I14: 3110300 | J14: =I14*G14 -> 12441200 | K14: 602.21/905/423.109/2020 | L14: 44077 | M14: Tangga
A15: 6 | B15: 44077 | C15: PT. COBAS KARAYA NUSANTARA | D15: 101/PP/CBS/III/2020 | E15: 44077 | F15: Denko Multi Purpos Teleskopic | G15: 2 | H15: unit | I15: 3827100 | J15: =I15*G15 -> 7654200 | K15: 602.21/905/423.109/2020 | L15: 44077 | M15: Tangga
A16: 7 | B16: 19/2/2020 | C16: STIGA Baut & Handtools | E16: 19/2/2020 | F16: tool kit listrik TEKIRO | G16: 1 | H16: unit | I16: 4975000 | J16: =I16*G16 -> 4975000 | K16: 600/507/423.109/2020 | L16: 44076 | M16: tool kit listrik (reklas instalasi listrik)
G17: jumlah total | J17: =SUM(J10:J16) -> 89535120
A20: MENGETAHUI | J20: Pasuruan, 31 Maret 2020
A21: KEPALA DINAS PERUMAHAN RAKYAT
A22: DAN KAWASAN PERMUKIMAN | J22: PENGURUS BARANG PENGGUNA
A26: DYAH ERMITASARI ST, MT | J26: INDRA ARDRIYARDHI
A27: NIP. 19721105 199803 2 012 | I27: NIP 19861022 201001 1 014
A29: SKPD | C29: : DINAS PERUMAHAN RAKYAT DAN KAWASAN PERMUKIMAN
A30: KOTA | C30: : PASURUAN
A31: PROVINSI | C31: : JAWA TIMUR
A32: BUKU PENERIMAAN BARANG INVENTARIS TRIBULAN II SEMESTER I TAHUN ANGGARAN 2020
A34: No | B34: Tanggal | C34: Dari | D34: Dokumen Faktur | F34: Nama Barang | G34: Banyaknya | I34: Harga Satuan | J34: Jumlah Harga | K34: Bukti Penerimaan | M34: Ket.
K35: B.A. Penerimaan
D36: Nomor | E36: Tanggal | K36: Nomor | L36: Tanggal
A37: 1 | B37: 2 | C37: 3 | D37: 4 | E37: 5 | F37: 6 | G37: 7 | I37: 8 | J37: 9 | K37: 10 | L37: 11 | M37: 12
A38: 1 | B38: 18/03/2020 | C38: CV. SOLUSI ARYA PRIMA | D38: AIRI20SUB 202100086 | E38: 18/03/2020 | F38: TENO TN-727 Ultimate Dual Band | G38: 5 | H38: unit | I38: 1933400 | J38: =I38*G38 -> 9667000 | K38: 602.21/1115/423.109/2020 | L38: 18/03/2020 | M38: Handy Talkie
A39: 2 | B39: 18/03/2020 | C39: CV. SOLUSI ARYA PRIMA | D39: AIRI20SUB 202100086 | E39: 18/03/2020 | F39: TENO TN-727 Ultimate Dual Band | G39: 1 | H39: unit | I39: 1933000 | J39: =I39*G39 -> 1933000 | K39: 602.21/1115/423.109/2020 | L39: 18/03/2020 | M39: Handy Talkie
A40: 3 | B40: 44078 | C40: PT WAHANA SAHABAT UTAMA | D40: FJ/WSUMLG/05/04/2020 | E40: 44078 | F40: NK 200 L | G40: 2 | H40: unit | I40: 27500000 | J40: =I40*G40 -> 55000000 | K40: 602.21/1775/423.109/2020 | L40: 44078 | M40: Roda 3
A41: 4 | B41: 22/4/2020 | C41: PT. SUN STAR MOTOR PROBOLINGGO | D41: 892 | E41: 22/4/2020 | F41: Mitsubishi L300 | G41: 1 | H41: Unit | I41: 176000000 | J41: =I41*G41 -> 176000000 | K41: 602.21/2055/423.109/2020 | L41: 23/4/2020 | M41: Pick up
A42: 5 | B42: 26/4/2020 | C42: CV. SOLUSI ARYA PRIMA | D42: 3319/SAP.PPh/JATIM/III/2020 | E42: 26/4/2020 | F42: TIGER 4 LACI FC-D4A | G42: 3 | H42: unit | I42: 2900025 | J42: =I42*G42 -> 8700075 | K42: 602.21/1123/423.109/2020 | L42: 26/4/2020 | M42: Filling Kabinet 4 Laci
A43: 6 | B43: 28/4/2020 | C43: PT. COBAS KARAYA NUSANTARA | D43: 72/CBS/IX/2020 | E43: 28/4/2020 | F43: Wagner WG-620-24L | G43: 4 | H43: unit | I43: 3109400 | J43: =I43*G43 -> 12437600 | K43: 602.21/2201/423.109/2020 | L43: 28/4/2020 | M43: Chainsaw
A44: 7 | B44: 28/4/2020 | C44: PT. COBAS KARAYA NUSANTARA | D44: 72/CBS/IX/2020 | E44: 28/4/2020 | F44: Wagner WB-350 | G44: 5 | H44: unit | I44: 2977500 | J44: =I44*G44 -> 14887500 | K44: 602.21/2201/423.109/2020 | L44: 28/4/2020 | M44: Mesin Pemotong rumput
G46: jumlah total | J46: =SUM(J41:J45) -> 212025175
A49: MENGETAHUI | K49: Pasuruan, 31 Maret 2020
A50: KEPALA DINAS PERUMAHAN RAKYAT
A51: DAN KAWASAN PERMUKIMAN | K51: PENGURUS BARANG PENGGUNA
...

Sheet LAMP.10 (II)
N1: LAMPIRAN 10
B2: SKPD | C2: DINAS PEKERJAAN UMUM
B3: KAB/KOTA | C3: PASURUAN
B4: PROVINSI | C4: JAWA TIMUR
A6: BUKU BARANG INVENTARIS
A8: PENERIMAAN | J8: PENGELUARAN
A9: No | B9: Tanggal diterima | C9: Nama/Jenis Barang | D9: Merk/ Ukuran | E9: Tahun Pembuatan | F9: Jumlah/ satuan | G9: Tgl/No.Kontrak/SP/SPK | H9: Berita Acara Pemeriksaan | J9: Tanggal Dikeluarkan | K9: Diserahkan Kepada | L9: Jumlah Satuan/Barang | M9: Tgl/No.Surat Penyerahan | N9: Keterangan
H10: Tanggal | I10: Nomor
A11: 1 | B11: 2 | C11: 3 | D11: 4 | E11: 5 | F11: 6 | G11: 7 | H11: 8 | I11: 9 | J11: 10 | K11: 11 | L11: 12 | M11: 13 | N11: 14
A13: 1 | B13: 42466 | C13: Pick Up | D13: Isuzu FD VIN Black | E13: 2016 | F13: 1 unit | G13: 602.1/196.14/423.108/2016 | H13: 42466 | I13: 602.21/374.7/423.108/2016 | J13: =B13 -> 42466 | K13: Bid. Pengairan | L13: =F13 -> 1 unit
A14: 2 | B14: 42467 | C14: PC | D14: HP Dekstop 455-011D + Led Monitor 18.5" | E14: 2016 | F14: 3 unit | G14: 602.1/313.15/423.108/2016 | H14: 42466 | I14: 602.21/374.3/423.108/2016 | J14: =B14 -> 42467 | K14: Sekretariat | L14: =F14 -> 3 unit
A15: 3 | B15: 42467 | C15: Notebook | D15: Acer One Z1402 | E15: 2016 | F15: 5 unit | G15: 602.1/313.15/423.108/2016 | H15: 42466 | I15: 602.21/374.3/423.108/2016 | J15: =B15 -> 42467 | K15: Sekretariat | L15: =F15 -> 5 unit
A16: 4 | B16: 42467 | C16: Printer A4 | D16: EPSON L310 | E16: 2016 | F16: 5 unit | G16: 602.1/313.15/423.108/2016 | H16: 42466 | I16: 602.21/374.3/423.108/2016 | J16: =B16 -> 42467 | K16: Sekretariat | L16: =F16 -> 5 unit
A17: 5 | B17: 42467 | C17: Kamera LSR | D17: Canon EOS 700D Kit1 18MP | E17: 2016 | F17: 1 unit | G17: 602.1/313.15/423.108/2016 | H17: 42466 | I17: 602.21/374.3/423.108/2016 | J17: =B17 -> 42467 | K17: Sekretariat | L17: =F17 -> 1 unit
A18: 6 | B18: 42472 | C18: Air Conditioner | D18: AKARI 2 pK | E18: 2016 | F18: 1 unit | G18: 027/398.3/423.108/2016 | H18: - | I18: - | J18: =B18 -> 42472 | K18: Sekretariat | L18: =F18 -> 1 unit
A19: 7 | B19: 42472 | C19: Filing Cabinet | D19: Brother 4 laci | E19: 2016 | F19: 2 unit | G19: 027/398.4/423.108/2016 | H19: - | I19: - | J19: =B19 -> 42472 | K19: Sekretariat | L19: =F19 -> 2 unit
A20: 8 | B20: 42513 | C20: Mobil | D20: Toyota New Grand Avanza Veloz 1.3 M/T Vin 2016 | E20: 2016 | F20: 1 unit | G20: 602.1/200.32/423.108/2016 | H20: 42513 | I20: 600/10/PPHP-Brg/423.108/2016 | J20: =B20 -> 42513 | K20: Sekretariat | L20: =F20 -> 1 unit
A21: 9 | B21: 42513 | C21: Mobil | D21: Toyota All New Hilux Single Cabin STD M/T Bensin Vin 2016 | E21: 2016 | F21: 1 unit | G21: 602.1/200.32/423.108/2016 | H21: 42513 | I21: 600/10/PPHP-Brg/423.108/2016 | J21: =B21 -> 42513 | K21: Sekretariat | L21: =F21 -> 1 unit
L26: Pasuruan, 30 Juni 2016
C28: ATASAN LANGSUNG | L28: PENYIMPAN BARANG
C32: DYAH ERMITASARI,ST,MT | L32: MUKHAMMAD FIRLI
C33: NIP. 19721105 199803 2 012 | L33: NIP. 19830531 200604 1 010

Sheet LAMP.14
A1: SKPD | C1: : | D1: DINAS PEKERJAAN UMUM | X1: LAMPIRAN 14
A2: KAB / KOTA | C2: : | D2: PASURUAN
A3: PROVINSI | C3: : | D3: JAWA TIMUR
I4: LAPORAN SEMESTER TETANG PENERIMAAN DAN PENGELUARAN BARANG INVENTARIS
I5: SEMESTER I TAHUN 2016
A7: No | E7: Penerimaan | F7: Dokumen / Faktur | K7: Buku Penerimaan | P7: Surat Bon
B8: Terima | D8: Dari | E8: SPK/ | F8: Nomor | G8: Tanggal | H8: Banyaknya | I8: Nama | J8: Harga | K8: BA/Srt Penerimaan | M8: Ket | N8: No | O8: Pengeluaran | P8: Nomor | Q8: Tgl | R8: Untuk | S8: Banyaknya | T8: Nama | U8: Harga | V8: Jumlah | W8: Tgl | X8: Ket
B9: Tgl | E9: Perjanjian | I9: Barang | J9: Satuan | K9: Nomor | L9: Tanggal | N9: Urut | O9: Tgl | T9: Barang | U9: Satuan | V9: Harga | W9: Penyerahan
A10: 1 | B10: 2 | D10: 3 | E10: 4 | F10: 5 | G10: 6 | H10: 7 | I10: 8 | J10: 9 | K10: 10 | L10: 11 | M10: 12 | N10: 13 | O10: 14 | P10: 15 | Q10: 16 | R10: 17 | S10: 18 | T10: 19 | U10: 20 | V10: 21 | W10: 22 | X10: 23
A12: 1 | B12: 42412 | D12: CV. DMIKI INTERACTIVE | F12: 602.21/40.23/423.108/2016 | G12: 42387 | H12: 2 unit | I12: Mesin Potong Rumput Dorong Husqvarna J55L/ 56 cm | J12: =9000000*1.1 -> 9900000 | K12: 602.21/151.7/423.108/2016 | L12: 42412 | O12: =B12 -> 42412 | R12: Bid. Persampahan & Pertamanan | S12: =H12 -> 2 unit | T12: =I12 -> Mesin Potong Rumput Dorong Husqvarna J55L/ 56 cm | U12: =J12 -> 9900000 | V12: =U12*2 -> 19800000 | W12: =O12 -> 42412
A13: 2 | B13: 42412 | D13: CV. DMIKI INTERACTIVE | F13: 602.21/40.23/423.108/2016 | G13: 42387 | H13: 1 unit | I13: Tangga Portable Geser Fiber t = 8,6m | J13: =12100000*1.1 -> 13310000 | K13: 602.21/151.7/423.108/2016 | L13: 42412 | O13: =B13 -> 42412 | R13: Bid. Persampahan & Pertamanan | S13: =H13 -> 1 unit | T13: =I13 -> Tangga Portable Geser Fiber t = 8,6m | U13: =J13 -> 13310000 | V13: =U13*1 -> 13310000 | W13: =O13 -> 42412
A14: 3 | B14: 42412 | D14: CV. DMIKI INTERACTIVE | F14: 602.21/40.23/423.108/2016 | G14: 42387 | H14: 1 unit | I14: Tangga Portable Fiber t = 2,8m | J14: =2250000*1.1 -> 2475000 | K14: 602.21/151.7/423.108/2016 | L14: 42412 | O14: =B14 -> 42412 | R14: Bid. Persampahan & Pertamanan | S14: =H14 -> 1 unit | T14: =I14 -> Tangga Portable Fiber t = 2,8m | U14: =J14 -> 2475000 | V14: =U14*1 -> 2475000 | W14: =O14 -> 42412
A15: 4 | B15: 42424 | D15: UD. VENA FLORIS | F15: 027/187.27/423.108/2016 | H15: 8 batang | I15: Tanaman Pagoda t= 2m daun | J15: 2000000 | K15: 602.21/196.31/423.108/2016 | L15: 42424 | O15: =B15 -> 42424 | R15: Bid. Persampahan & Pertamanan | S15: =H15 -> 8 batang | T15: =I15 -> Tanaman Pagoda t= 2m daun | U15: =J15 -> 2000000 | V15: =U15*1 -> 2000000 | W15: =O15 -> 42424
A16: 5 | B16: 42424 | D16: CV. MUTIARA RAJAWALI | F16: 602.21/146/423.108/2016 | G16: 42411 | H16: 1 unit | I16: Perahu Sampan Kayu | J16: =28330000*1.1 -> 31163000 | K16: 602.21/196.23/423.108/2016 | L16: 42424 | O16: =B16 -> 42424 | R16: Bid. Pengairan | S16: =H16 -> 1 unit | T16: =I16 -> Perahu Sampan Kayu | U16: =J16 -> 31163000 | V16: =U16*1 -> 31163000 | W16: =O16 -> 42424
A17: 6 | B17: 42443 | D17: PT. ASTRA INTERNATIONAL Tbk ISUZU | F17: 602.1/196.16/423.108/2016 | G17: 42424 | H17: 1 unit | I17: Pick Up Isuzu GD VIN Black | J17: 165689406 | K17: 602.21/260.3/423.108/2016 | L17: 42443 | O17: =B17 -> 42443 | R17: Bid. Persampahan & Pertamanan | S17: =H17 -> 1 unit | T17: =I17 -> Pick Up Isuzu GD VIN Black | U17: =J17 -> 165689406 | V17: =U17*1 -> 165689406 | W17: =O17 -> 42443
A18: 7 | B18: 42450 | D18: CV. DMIKI INTERACTIVE | F18: 602.21/115.12/423.108/2016 | G18: 42402 | H18: 10 unit | I18: Meja Kerja Staf Kayu Jati + Kaca 120x60x75 cm | J18: =1575000*1.1 -> 1732500 | K18: 602.21/290.4/423.108/2016 | L18: 42450 | O18: =B18 -> 42450 | R18: Sekretariat | S18: =H18 -> 10 unit | T18: =I18 -> Meja Kerja Staf Kayu Jati + Kaca 120x60x75 cm | U18: =J18 -> 1732500 | V18: =U18*10 -> 17325000 | W18: =O18 -> 42450
A19: 8 | B19: 42450 | D19: CV. DMIKI INTERACTIVE | F19: 602.21/115.12/423.108/2016 | G19: 42402 | H19: 2 unit | I19: Meja Kerja Eselon Kayu Jati + Kaca 150x75x75 cm | J19: =2550000*1.1 -> 2805000 | K19: 602.21/290.4/423.108/2016 | L19: 42450 | O19: =B19 -> 42450 | R19: Sekretariat | S19: =H19 -> 2 unit | T19: =I19 -> Meja Kerja Eselon Kayu Jati + Kaca 150x75x75 cm | U19: =J19 -> 2805000 | V19: =U19*2 -> 5610000 | W19: =O19 -> 42450
A20: 9 | B20: 42450 | D20: CV. DMIKI INTERACTIVE | F20: 602.21/115.12/423.108/2016 | G20: 42402 | H20: 5 unit | I20: Kursi Kerja Eselon RAISER R-2010 | J20: =1275000*1.1 -> 1402500 | K20: 602.21/290.4/423.108/2016 | L20: 42450 | O20: =B20 -> 42450 | R20: Sekretariat | S20: =H20 -> 5 unit | T20: =I20 -> Kursi Kerja Eselon RAISER R-2010 | U20: =J20 -> 1402500 | V20: =U20*5 -> 7012500 | W20: =O20 -> 42450
A21: 10 | B21: 42450 | D21: CV. DMIKI INTERACTIVE | F21: 602.21/115.12/423.108/2016 | G21: 42402 | H21: 23 unit | I21: Kursi Kerja Staf ALVERO | J21: =760000*1.1 -> 836000 | K21: 602.21/290.4/423.108/2016 | L21: 42450 | O21: =B21 -> 42450 | R21: Sekretariat | S21: =H21 -> 23 unit | T21: =I21 -> Kursi Kerja Staf ALVERO | U21: =J21 -> 836000 | V21: =U21*23 -> 19228000 | W21: =O21 -> 42450
A22: 11 | B22: 42450 | D22: CV. DMIKI INTERACTIVE | F22: 602.21/115.12/423.108/2016 | G22: 42402 | H22: 1 unit | I22: Lemari Arsip Kayu Jati + Kaca 183x88x45 cm | J22: =2645000*1.1 -> 2909500 | K22: 602.21/290.4/423.108/2016 | L22: 42450 | O22: =B22 -> 42450 | R22: Sekretariat | S22: =H22 -> 1 unit | T22: =I22 -> Lemari Arsip Kayu Jati + Kaca 183x88x45 cm | U22: =J22 -> 2909500 | V22: =U22*1 -> 2909500 | W22: =O22 -> 42450
A23: 12 | B23: 42450 | D23: CV. DMIKI INTERACTIVE | F23: 602.21/115.12/423.108/2016 | G23: 42402 | H23: 5 unit | I23: Kursi Lipat Chitose (Hitam) Rangka Crome | J23: =250000*1.1 -> 275000 | K23: 602.21/290.4/423.108/2016 | L23: 42450 | O23: =B23 -> 42450 | R23: Sekretariat | S23: =H23 -> 5 unit | T23: =I23 -> Kursi Lipat Chitose (Hitam) Rangka Crome | U23: =J23 -> 275000 | V23: =U23*5 -> 1375000 | W23: =O23 -> 42450
A24: 13 | B24: 42450 | D24: Toko "VENA FLORIS" | F24: 027/281.7/423.108/2016 | G24: 42446 | H24: 6 batang | I24: Palem Bismarkia Silver t = 2 m daun | J24: 2300000 | K24: 602.21/290.4/423.108/2016 | L24: 42450 | O24: =B24 -> 42450 | R24: Bid. Persampahan & Pertamanan | S24: =H24 -> 6 batang | T24: =I24 -> Palem Bismarkia Silver t = 2 m daun | U24: =J24 -> 2300000 | V24: =U24*6 -> 13800000 | W24: =O24 -> 42450
A25: 14 | B25: 42457 | D25: PT. TRAKINDO UTAMA | F25: 602.1/186.2/423.108/2016 | G25: 42422 | H25: 1 unit | I25: Excavator Mini CAT 304ECR/CAN/0.16CUM/Steel Track | J25: =590909100*1.1 -> 650000010 | K25: 600/328.2/423.108/2016 | L25: 42457 | O25: =B25 -> 42457 | R25: UPT Lab. Uji Mutu & Bahan | S25: =H25 -> 1 unit | T25: =I25 -> Excavator Mini CAT 304ECR/CAN/0.16CUM/Steel Track | U25: =J25 -> 650000010 | V25: =U25*1 -> 650000010 | W25: =O25 -> 42457
A26: 15 | B26: 42466 | D26: PT. ASTRA INTERNATIONAL Tbk ISUZU | F26: 602.1/196.14/423.108/2016 | G26: 42424 | H26: 1 unit | I26: Pick Up Isuzu FD VIN Black | J26: 164748406 | K26: 602.21/374.6/423.108/2016 | L26: 42466 | O26: =B26 -> 42466 | R26: Bid. Pengairan | S26: =H26 -> 1 unit | T26: =I26 -> Pick Up Isuzu FD VIN Black | U26: =J26 -> 164748406 | V26: =U26*1 -> 164748406 | W26: =O26 -> 42466
A27: 16 | B27: 42467 | D27: PT. BHINNEKA MENTARIDIMENSI | F27: 602.1/313.15/423.108/2016 | G27: 42452 | H27: 3 unit | I27: PC HP Dekstop 455-011D + Led Monitor 18.5" | J27: 7180000 | K27: 602.21/376.1/423.108/2016 | L27: 42467 | O27: =B27 -> 42467 | R27: Sekretariat | S27: =H27 -> 3 unit | T27: =I27 -> PC HP Dekstop 455-011D + Led Monitor 18.5" | U27: =J27 -> 7180000 | V27: =U27*3 -> 21540000 | W27: =O27 -> 42467
A28: 17 | B28: 42467 | D28: PT. BHINNEKA MENTARIDIMENSI | F28: 602.1/313.15/423.108/2016 | G28: 42452 | H28: 5 unit | I28: Notebook Acer One Z1402 | J28: 5444000 | K28: 602.21/376.1/423.108/2016 | L28: 42467 | O28: =B28 -> 42467 | R28: Sekretariat | S28: =H28 -> 5 unit | T28: =I28 -> Notebook Acer One Z1402 | U28: =J28 -> 5444000 | V28: =U28*5 -> 27220000 | W28: =O28 -> 42467
A29: 18 | B29: 42467 | D29: PT. BHINNEKA MENTARIDIMENSI | F29: 602.1/313.15/423.108/2016 | G29: 42452 | H29: 5 unit | I29: Printer EPSON L310 | J29: 1950000 | K29: 602.21/376.1/423.108/2016 | L29: 42467 | O29: =B29 -> 42467 | R29: Sekretariat | S29: =H29 -> 5 unit | T29: =I29 -> Printer EPSON L310 | U29: =J29 -> 1950000 | V29: =U29*5 -> 9750000 | W29: =O29 -> 42467
A30: 19 | B30: 42467 | D30: PT. BHINNEKA MENTARIDIMENSI | F30: 602.1/313.15/423.108/2016 | G30: 42452 | H30: 1 unit | I30: Kamera LSR Canon EOS 700D Kit1 18MP | J30: 8599500 | K30: 602.21/376.1/423.108/2016 | L30: 42467 | O30: =B30 -> 42467 | R30: Sekretariat | S30: =H30 -> 1 unit | T30: =I30 -> Kamera LSR Canon EOS 700D Kit1 18MP | U30: =J30 -> 8599500 | V30: =U30*1 -> 8599500 | W30: =O30 -> 42467
A31: 20 | B31: 42472 | D31: GAYABARU Electronic | F31: 027/398.3/423.108/2016 | G31: 42471 | H31: 1 unit | I31: Air Conditioner AKARI 2 Pk | J31: 6500000 | K31: 600/404/423.108/2016 | L31: 42472 | O31: =B31 -> 42472 | R31: Sekretariat | S31: =H31 -> 1 unit | T31: =I31 -> Air Conditioner AKARI 2 Pk | U31: =J31 -> 6500000 | V31: =U31*1 -> 6500000 | W31: =O31 -> 42472
A32: 21 | B32: 42472 | D32: CV. AIR | F32: 027/398.4/423.108/2016 | G32: 42471 | H32: 2 unit | I32: Filing Cabinet Brother 4 laci | J32: 2100000 | K32: 600/405/423.108/2016 | L32: 42472 | O32: =B32 -> 42472 | R32: Sekretariat | S32: =H32 -> 2 unit | T32: =I32 -> Filing Cabinet Brother 4 laci | U32: =J32 -> 2100000 | V32: =U32*2 -> 4200000 | W32: =O32 -> 42472
A33: 22 | B33: 42513 | D33: PT. ASTRA INTERNATIONAL Tbk | F33: 602.1/200.32/423.108/2016 | G33: 42425 | H33: 1 unit | I33: Mobil Toyota New Grand Avanza Veloz 1.3 M/T Vin 2016 | J33: 194940000 | K33: 602.21/604/423.108/2016 | L33: 42513 | O33: =B33 -> 42513 | R33: Sekretariat | S33: =H33 -> 1 unit | T33: =I33 -> Mobil Toyota New Grand Avanza Veloz 1.3 M/T Vin 2016 | U33: =J33 -> 194940000 | V33: =U33*1 -> 194940000 | W33: =O33 -> 42513
A34: 23 | B34: 42513 | D34: PT. ASTRA INTERNATIONAL Tbk | F34: 602.1/200.32/423.108/2016 | G34: 42425 | H34: 1 unit | I34: Mobil Toyota All New Hilux Single Cabin STD M/T Bensin Vin 2016 | J34: 190740000 | K34: 602.21/604/423.108/2016 | L34: 42513 | O34: =B34 -> 42513 | R34: Sekretariat | S34: =H34 -> 1 unit | T34: =I34 -> Mobil Toyota All New Hilux Single Cabin STD M/T Bensin Vin 2016 | U34: =J34 -> 190740000 | V34: =U34*1 -> 190740000 | W34: =O34 -> 42513
S39: Pasuruan, 30 Juni 2016
T41: PENYIMPAN BARANG
T46: MUKHAMMAD FIRLI
T47: NIP. 19830531 200604 1 010
T183: Pasuruan, April 2010
T185: PENYIMPAN BARANG
T190: CHAIRUL ANWAR
T191: NIP. 19800128 200311 1 001

Sheet LAMP.15
A1: SKPD | C1: : | D1: DINAS PERUMAHAN RAKYAT DAN KAWASAN PERMUKIMAN | Y1: LAMPIRAN 15
A2: KAB / KOTA | C2: : | D2: PASURUAN
A3: PROVINSI | C3: : | D3: JAWA TIMUR
A4: LAPORAN SEMESTER TETANG PENERIMAAN DAN PENGELUARAN BARANG PAKAI HABIS
B5: SEMESTER I TAHUN 2021
A8: No | E8: Dokumen / Faktur | G8: Dasar Penerimaan | L8: Buku Penerimaan | Q8: Surat Bon
B9: Terima | D9: Dari | E9: Nomor | F9: Tgl | G9: Jenis | H9: Nomor | I9: Banyak | J9: Nama | K9: Harga | L9: BA/Srt Penerimaan | N9: Ket | O9: No | P9: Terima | Q9: No | R9: Tgl | S9: Untuk | T9: Bnyak | U9: Nama | V9: Harga | W9: Jumlah | X9: Tgl | Y9: Ket
B10: Tgl | G10: Surat | I10: nya | J10: Barang | K10: Satuan | L10: Nomor | M10: Tanggal | O10: Urut | P10: Tgl | T10: nya | U10: Brg | V10: Satuan | W10: Harga | X10: Penyerahan
A11: 1 | B11: 2 | D11: 3 | E11: 4 | F11: 5 | G11: 6 | H11: 7 | I11: 8 | J11: 9 | K11: 10 | L11: 11 | M11: 12 | N11: 13 | O11: 14 | P11: 15 | Q11: 16 | R11: 17 | S11: 18 | T11: 19 | U11: 20 | V11: 21 | W11: 22 | X11: 23 | Y11: 24
A13: ='LAMP.8 (I)'!A10 -> 1. Alat Tulis Kantor
V741: Pasuruan, 30 Juni 2019
E742: Mengetahui
D743: KEPALA DINAS PERUMAHAN RAKYAT DAN KAWASAN PERMUKIMAN | V743: PENYIMPAN BARANG
D744: KOTA PASURUAN
V747: MUSTOFA
D748: DYAH ERMITASARI,ST,MT | V748: NIP. 19720608 200701 1 020
D749: NIP. 19721105 199803 2 012

Sheet LAMP.8 (II)
M1: LAMPIRAN 8
A2: BUKU PENERIMAAN BARANG
A5: No | B5: Tanggal | C5: Dari | D5: Dokumen Faktur | F5: Nama Barang | G5: Banyaknya | I5: Harga Satuan (Rp.) | J5: Jumlah Harga (Rp.) | K5: Bukti Penerimaan/ | M5: Keterangan
K6: B.A. Penerimaan
D7: Nomor | E7: Tanggal | K7: Nomor | L7: Tanggal
A8: 1 | B8: 2 | C8: 3 | D8: 4 | E8: 5 | F8: 6 | G8: 7 | I8: 8 | J8: 9 | K8: 10 | L8: 11 | M8: 12
A10: 1. Alat Tulis Kantor
B13: 46165 | C13: CV "Centrojaya" | F13: lem Artline | G13: 6 | H13: buah | I13: 6105 | J13: =I13*G13 -> 36630 | K13: 003.2/400-3/104/2026 | L13: 46165
F14: Binder klip no 200 | G14: 8 | H14: pak | I14: 14430 | J14: =I14*G14 -> 115440
F15: pos it IM | G15: 6 | H15: buah | I15: 8880 | J15: =I15*G15 -> 53280
F16: Bolpen Tizo Gel | G16: 24 | H16: buah | I16: 5550 | J16: =I16*G16 -> 133200
F17: Paper clip no 5 | G17: 6 | H17: buah | I17: 7770 | J17: =G17*I17 -> 46620
F18: Binder klip no 260 | G18: 8 | H18: pak | I18: 22200 | J18: =I18*G18 -> 177600
F19: Bolpoin pilot | G19: 49 | H19: buah | I19: 3330 | J19: =I19*G19 -> 163170
F20: Amplop 104 | G20: 3 | H20: buah | I20: 21090 | J20: =I20*G20 -> 63270
F21: Isi Steples Max 10 | G21: 3 | H21: buah | I21: 5439 | J21: =I21*G21 -> 16317
F22: Map kancing | G22: 125 | H22: buah | I22: 4995 | J22: =I22*G22 -> 624375
F23: Map L | G23: 24 | H23: buah | I23: 2220 | J23: =I23*G23 -> 53280
F24: Map folio kertas | G24: 24 | H24: buah | I24: 2775 | J24: =I24*G24 -> 66600 | O24: =SUM(J13:J24) -> 1549782 | P24: PSU Perumahan
B26: 46169 | C26: CV "Centrojaya" | F26: Spidol Whiteboard Snowman | G26: 12 | H26: buah | I26: 9990 | J26: =I26*G26 -> 119880 | K26: 000.3/80.2-1/104/2026 | L26: 46169
F27: Bolpen Weiyada | G27: 120 | H27: buah | I27: 5439 | J27: =I27*G27 -> 652680
F28: Stabilo arteline | G28: 10 | H28: buah | I28: 9435 | J28: =G28*I28 -> 94350
F29: Map plastik kancing | G29: 50 | H29: buah | I29: 5439 | J29: =I29*G29 -> 271950
F30: Stabilo Joyco | G30: 2 | H30: buah | I30: 6438 | J30: =G30*I30 -> 12876 | O30: =SUM(J26:J30) -> 1151736 | P30: Belnja kegiatan kantor
B32: 46153 | C32: CV "Centrojaya" | F32: Correction tape | G32: 20 | H32: buah | I32: 13320 | J32: =I32*G32 -> 266400 | K32: 000.3/ -1/104/2026 | L32: 46153
F33: Lem UHU 8g | G33: 20 | H33: pak | I33: 13320 | J33: =I33*G33 -> 266400
F34: Bolpen Tizo Gel | G34: 60 | H34: buah | I34: 5550 | J34: =I34*G34 -> 333000
F35: Penggaris besi 30 cm | G35: 10 | H35: buah | I35: 16650 | J35: =G35*I35 -> 166500
F36: Post it Plastik | G36: 50 | H36: pak | I36: 7770 | J36: =I36*G36 -> 388500
F37: Spidol marker Snawman | G37: 15 | H37: buah | I37: 9990 | J37: =I37*G37 -> 149850
F38: Dokumen keeper isi 20 | G38: 30 | H38: buah | I38: 18870 | J38: =I38*G38 -> 566100
F39: Binder clip 105 | G39: 50 | H39: buah | I39: 4995 | J39: =I39*G39 -> 249750
F40: Amplop 104 | G40: 10 | H40: buah | I40: 19980 | J40: =I40*G40 -> 199800
F41: Spidol Whiteboar Snawman | G41: 15 | H41: buah | I41: 10545 | J41: =I41*G41 -> 158175
F42: Map L | G42: 50 | H42: buah | I42: 4995 | J42: =I42*G42 -> 249750
F43: Bolpen Kenko | G43: 60 | H43: buah | I43: 4995 | J43: =I43*G43 -> 299700
F44: Binder clip 260 | G44: 25 | H44: buah | I44: 23310 | J44: =I44*G44 -> 582750
F45: Stabilo warna | G45: 15 | H45: buah | I45: 14430 | J45: =I45*G45 -> 216450 | O45: =SUM(J32:J45) -> 4093125 | P45: Belnja kegiatan kantor
B47: 46146 | C47: LUKMAN CHAKIM | F47: Amplop 104 | G47: 4 | H47: buah | I47: 27750 | J47: =I47*G47 -> 111000 | K47: 003.2/432-4/104/2026 | L47: 46146
F48: Odner besar folio | G48: 3 | H48: buah | I48: 44400 | J48: =I48*G48 -> 133200
...

Sheet LAMP.9 (II)
K1: LAMPIRAN 9
A3: BUKU PENGELUARAN BARANG
A6: No. | B6: Tanggal | C6: Nomor Urut | D6: Nama Barang | E6: Banyaknya | G6: Harga Satuan | H6: Jumlah Harga | I6: Untuk | J6: Tanggal Penyerahan | K6: Ket
A8: 1 | B8: 2 | C8: 3 | D8: 4 | E8: 5 | G8: 6 | H8: 7 | I8: 8 | J8: 9 | K8: 10
A10: ='LAMP.8 (II)'!A10:M10 -> 1. Alat Tulis Kantor
J443: Pasuruan, 31 Maret 2022
C445: ATASAN LANGSUNG | J445: PENGURUS BARANG
C449: DYAH ERMITASARI,ST,MT | J449: ADE CANDRA WAHYU DARMAWAN
C450: NIP. 19721105 199803 2 012 | J450: NIP. 199606132020121009

Sheet LAMP.11 (II)
P1: LAMPIRAN 11
B2: SKPD | C2: DINAS PERUMAHAN RAKYAT DAN KAWASAN PERMUKIMAN
B3: KAB/KOTA | C3: PASURUAN
B4: PROVINSI | C4: JAWA TIMUR
A6: BUKU BARANG PAKAI HABIS
B8: PENERIMAAN | K8: PENGELUARAN
A9: No | B9: Tanggal diterima | C9: Jenis/Nama Barang | D9: Merk/ Ukuran | E9: Tahun Pembuatan | F9: Jumlah satuan/ barang | H9: Tgl/No.Kontrak/SP/SPK/harga satuan | I9: Berita Acara Pemeriksaan | K9: Tanggal Dikeluarkan | L9: Diserahkan Kepada | M9: Jumlah satuan/ barang | O9: Tgl/No.Surat Penyerahan | P9: Keterangan
I10: Tanggal | J10: Nomor
A11: 1 | B11: 2 | C11: 3 | D11: 4 | E11: 5 | F11: 6 | H11: 7 | I11: 8 | J11: 9 | K11: 10 | L11: 11 | M11: 12 | O11: 13 | P11: 14
A13: ='LAMP.8 (II)'!A10:M10 -> 1. Alat Tulis Kantor
N446: Pasuruan, 30 Juni 2021
C448: ATASAN LANGSUNG | N448: PENGURUS BARANG
C452: DYAH ERMITASARI,ST,MT | N452: ADE CANDRA WAHYU DARMAWAN
C453: NIP. 19721105 199803 2 012 | N453: NIP. 199606132020121009

Sheet LAMP.16
G1: LAMPIRAN 16
A4: SKPD | B4: DINAS PEKERJAAN UMUM | F4: No.
A5: KAB/KOTA | B5: PASURUAN
A7: BUKTI PENGAMBILAN BARANG DARI GUDANG….
A10: Tanggal Penyerahan Barang Menurut Permintaan | B10: Barang Diterima dari Gudang | C10: Nama & Kode Barang | D10: Satuan | E10: Jumlah | F10: Barang | G10: Jumlah Harga
A11: 1 | B11: 2 | C11: 3 | D11: 4 | E11: 5 | F11: 6 | G11: 7
I13: Penyusunan Pelaporan Barang SKPD dan Pengelolaan Kepegawaian ( Barang Inventaris Tribulan I dan Laporan SKP Tahun 2014 )
A25: DINAS PEKERJAAN UMUM KOTA PASURUAN
A26: 1 Januari 2015 | F26: Pasuruan, 1 Januari 2015
F29: Yang menyerahkan
A30: Yang menerima | F30: Penyimpan Barang
A33: Tanda Tangan | E33: Tanda Tangan
A35: Nama | E35: Nama
A36: NIP | E36: NIP
A37: Pangkat/Gol. | E37: Pangkat/Gol.
A39: MENGETAHUI
A40: a.n. PENGGUNA BARANG
A41: (ATASAN LANGSUNG PENYIMPAN BARANG)
C44: TANDA TANGAN
C46: NAMA
C47: PANGKAT/GOL.
C48: JABATAN

Sheet Sheet1
B1: PERTALIT dek | C1: PERTAMAX 1 | D1: DEX | E1: PREMIUM
B2: 7650 | C2: 9000 | D2: 10200 | E2: 7650
B4: 53550 | C4: 243000 | D4: 1468800
C5: 126000 | D5: 367200
C6: 162000 | D6: 367200
C7: 288000
B14: =SUM(B3:B13) -> 53550 | C14: =SUM(C3:C13) -> 819000 | D14: =SUM(D3:D13) -> 2203200 | E14: =SUM(E3:E13) -> 0 | F14: =SUM(B14:E14) -> 3075750
A15: LITER | B15: =B14/B2 -> 7 | C15: =C14/C2 -> 91 | D15: =D14/D2 -> 216 | E15: =E14/E2 -> 0

Sheet Sheet2
A1: 56800 | B1: 16 | C1: =A1*B1 -> 908800
A2: 352500 | B2: 0.4 | C2: =A2*B2 -> 141000
A3: 175500 | B3: 5 | C3: =A3*B3 -> 877500
A4: 700 | B4: 1254 | C4: =A4*B4 -> 877800
A5: 48250 | B5: 16 | C5: =A5*B5 -> 772000
A6: 4050000 | B6: 0.1 | C6: =A6*B6 -> 405000
A7: 70000 | B7: 2 | C7: =A7*B7 -> 140000
A8: 68500 | B8: 8 | C8: =A8*B8 -> 548000
A9: 2300 | B9: 15 | C9: =A9*B9 -> 34500
A10: 15000 | B10: 92 | C10: =A10*B10 -> 1380000
C11: =SUM(C1:C10) -> 6084600

Sheet Sheet3
