Workbook

Sheet Full
B1: Kartu Barang
A3: 1 | B3: Nama Barang : | C3: Amplop putih 90
B4: Satuan : | C4: box
B6: Tanggal | C6: Harga Pembelian per satuan | D6: Jumlah Barang | G6: Nilai Penerimaan Barang Persediaan
D7: Masuk | E7: Keluar | F7: Sisa
B8: 46024 | C8: 27750 | D8: 2 | F8: =D8-E8 -> 2 | G8: =C8*D8 -> 55500
G9: =C9*D9 -> 0
G10: =C10*D10 -> 0
G11: =C11*D11 -> 0
G12: =C12*D12 -> 0
G13: =C13*D13 -> 0
G14: =C14*D14 -> 0
G15: =C15*D15 -> 0
G16: =C16*D16 -> 0
G17: =C17*D17 -> 0
G18: =C18*D18 -> 0
G19: =C19*D19 -> 0
G20: =C20*D20 -> 0
... G25: =C25*D25 -> 0
H32: 0 | I32: sekretariat
H33: 0 | I33: Upt rusunawa
H34: 0 | I34: Bidang perumahan
H35: 1 | I35: Bidang Permukiman
B36: Jumlah | D36: =SUM(D8:D35) -> 2 | E36: =SUM(E8:E35) -> 0 | F36: =D36-E36 -> 2 | G36: =SUM(G8:G31) -> 55500 | H36: 0 | I36: upt makam
B38: Keterangan | F38: Jumlah | G38: Nilai
B39: Saldo Awal 2 Jan 2026 | F39: =D8 -> 2 | G39: =G8 -> 55500
B40: Nilai Penerimaan Barang Persediaan Tahun 2026 | F40: =D36-F39 -> 0 | G40: =G36-G39 -> 0
B41: Saldo Akhir 31 Maret 2026 | F41: =SUM(B44:B47) -> 2 | G41: =SUM(D44:E47) -> 55500
B42: Rincian: Metode Penilaian FIFO
B43: Jumlah Barang | C43: Harga Satuan | D43: Nilai
B44: =F36 -> 2 | C44: 27750 | D44: =B44*C44 -> 55500
B48: Persediaan Yang Digunakan (Beban Persediaan) | F48: =F39+F40-F41 -> 0 | G48: =G39+G40-G41 -> 0
B50: Kartu Barang
A52: 2 | B52: Nama Barang : | C52: ='Rekap Master'!B11 -> Amplop putih 104
B53: Satuan : | C53: box
B55: Tanggal | C55: Harga Pembelian per satuan | D55: Jumlah Barang | G55: Nilai Penerimaan Barang Persediaan
D56: Masuk | E56: Keluar | F56: Sisa
B57: =B8 -> 46024 | C57: 21800 | D57: 9 | E57: 0 | F57: =D57-E57 -> 9 | G57: =C57*D57 -> 196200
G58: =C58*D58 -> 0
G59: =C59*D59 -> 0
...

Sheet Rekap Full
B1: Kartu Barang
A3: 1 | B3: Nama Barang : | C3: Amplop putih 90 | N3: ATK
B4: Satuan : | C4: box | N4: =N3 -> ATK
N5: =N4 -> ATK
B6: Tanggal | C6: Harga Pembelian per satuan | D6: Jumlah Barang | G6: Nilai Penerimaan Barang Persediaan | N6: =N5 -> ATK
D7: Masuk | E7: Keluar | F7: Sisa | N7: =N6 -> ATK
B8: 46024 | C8: 27750 | D8: 2 | F8: =D8-E8 -> 2 | G8: =C8*D8 -> 55500 | N8: =N7 -> ATK
G9: =C9*D9 -> 0 | N9: =N8 -> ATK
G10: =C10*D10 -> 0 | N10: =N9 -> ATK
G11: =C11*D11 -> 0 | N11: =N10 -> ATK
G12: =C12*D12 -> 0 | N12: =N11 -> ATK
G13: =C13*D13 -> 0 | N13: =N12 -> ATK
G14: =C14*D14 -> 0 | N14: =N13 -> ATK
G15: =C15*D15 -> 0 | N15: =N14 -> ATK
G16: =C16*D16 -> 0 | N16: =N15 -> ATK
G17: =C17*D17 -> 0 | N17: =N16 -> ATK
G18: =C18*D18 -> 0 | N18: =N17 -> ATK
G19: =C19*D19 -> 0 | N19: =N18 -> ATK
G20: =C20*D20 -> 0 | N20: =N19 -> ATK
... G25: =C25*D25 -> 0 | N25: =N24 -> ATK
N26: =N25 -> ATK
N27: =N26 -> ATK
N28: =N27 -> ATK
N29: =N28 -> ATK
N30: =N29 -> ATK
N31: =N30 -> ATK
H32: 0 | I32: sekretariat | N32: =N31 -> ATK
H33: 0 | I33: Upt rusunawa | N33: =N32 -> ATK
H34: 0 | I34: Bidang perumahan | N34: =N33 -> ATK
H35: 1 | I35: Bidang Permukiman | N35: =N34 -> ATK
B36: Jumlah | D36: =SUM(D8:D35) -> 2 | E36: =SUM(E8:E35) -> 0 | F36: =D36-E36 -> 2 | G36: =SUM(G8:G31) -> 55500 | H36: 0 | I36: upt makam | N36: =N35 -> ATK
N37: =N36 -> ATK
B38: Keterangan | F38: Jumlah | G38: Nilai | N38: =N37 -> ATK
B39: Saldo Awal 2 Jan 2026 | F39: =D8 -> 2 | G39: =G8 -> 55500 | N39: =N38 -> ATK
B40: Nilai Penerimaan Barang Persediaan Tahun 2026 | F40: =D36-F39 -> 0 | G40: =G36-G39 -> 0 | N40: =N39 -> ATK
B41: Saldo Akhir 31 Maret 2026 | F41: =SUM(B44:B47) -> 2 | G41: =SUM(D44:E47) -> 55500 | N41: =N40 -> ATK
B42: Rincian: Metode Penilaian FIFO | N42: =N41 -> ATK
B43: Jumlah Barang | C43: Harga Satuan | D43: Nilai | N43: =N42 -> ATK
B44: =F36 -> 2 | C44: 27750 | D44: =B44*C44 -> 55500 | N44: =N43 -> ATK
N45: =N44 -> ATK
...

Sheet Rekap Master
A1: LAPORAN MUTASI BARANG PERSEDIAAN
A2: ALAT TULIS KANTOR
A3: DINAS PERUMAHAN RAKYAT DAN KAWASAN PERMUKIMAN
A5: No | B5: Rincian Nama Persediaan | C5: Saldo Per 2 Januari 2024 | E5: Penambahan | G5: Pengurangan | I5: Saldo Per 30 Januari 2024 | K5: Hasil Stock Opname | N5: Selisih | P5: Keterangan
C7: Jumlah | D7: Nilai Persediaan (Rp) | E7: =C7 -> Jumlah | F7: =D7 -> Nilai Persediaan (Rp) | G7: =E7 -> Jumlah | H7: =F7 -> Nilai Persediaan (Rp) | I7: =G7 -> Jumlah | J7: =H7 -> Nilai Persediaan (Rp) | K7: =I7 -> Jumlah | L7: =J7 -> Nilai Persediaan (Rp) | M7: *Kondisi | N7: Jumlah | O7: Nilai Persediaan (Rp)
A9: 1 | B9: 2 | C9: 3 | D9: 4 | E9: 5 | F9: 6 | G9: 7 | H9: 8 | I9: 9 (3+5-7) | J9: 10 (4+6-8) | K9: 11 | L9: 12 | M9: 13 | N9: 14 (9-11) | O9: 15 (10-12) | P9: 16
A10: 1 | B10: Amplop putih 90 | C10: =Full!F39 -> 2 | D10: =Full!G39 -> 55500 | E10: =Full!F40 -> 0 | F10: =Full!G40 -> 0 | G10: =Full!F48 -> 0 | H10: =Full!G48 -> 0 | I10: =Full!F41 -> 2 | J10: =Full!G41 -> 55500 | K10: =I10 -> 2 | L10: =J10 -> 55500
A11: 2 | B11: Amplop putih 104 | C11: =Full!F83 -> 9 | D11: =Full!G83 -> 196200 | E11: =Full!F84 -> 0 | F11: =Full!G84 -> 0 | G11: =Full!F92 -> 0 | H11: =Full!G92 -> 0 | I11: =Full!F85 -> 9 | J11: =Full!G85 -> 196200 | K11: =I11 -> 9 | L11: =J11 -> 196200
A12: 3 | B12: Binderclips Joyko 260 | C12: =Full!F124 -> 7 | D12: =Full!G124 -> 159285 | E12: =Full!F125 -> 0 | F12: =Full!G125 -> 0 | G12: =Full!F133 -> 0 | H12: =Full!G133 -> 0 | I12: =Full!F126 -> 7 | J12: =Full!G126 -> 159285 | K12: =I12 -> 7 | L12: =J12 -> 159285
A13: 4 | B13: Ballpoint Snowman V-5 0,7 mm | C13: =Full!F156 -> 0 | D13: =Full!G156 -> 0 | E13: =Full!F157 -> 0 | F13: =Full!G157 -> 0 | G13: =Full!F165 -> 0 | H13: =Full!G165 -> 0 | I13: =Full!F158 -> 0 | J13: =Full!G158 -> 0 | K13: =I13 -> 0 | L13: =J13 -> 0
A14: 5 | B14: Ballpoint pentel plus isi | C14: =Full!F185 -> 0 | D14: =Full!G185 -> 0 | E14: =Full!F186 -> 0 | F14: =Full!G186 -> 0 | G14: =Full!F194 -> 0 | H14: =Full!G194 -> 0 | I14: =Full!F187 -> 0 | J14: =Full!G187 -> 0 | K14: =I14 -> 0 | L14: =J14 -> 0
A15: 6 | B15: Binder Clips 107 | C15: =Full!F226 -> 3 | D15: =Full!G226 -> 34500 | E15: =Full!F227 -> 0 | F15: =Full!G227 -> 0 | G15: =Full!F235 -> 0 | H15: =Full!G235 -> 0 | I15: =Full!F228 -> 3 | J15: =Full!G228 -> 34500 | K15: =I15 -> 3 | L15: =J15 -> 34500
A16: 7 | B16: Binderclips 200 | C16: =Full!F267 -> 5 | D16: =Full!G267 -> 70000 | E16: =Full!F268 -> 0 | F16: =Full!G268 -> 0 | G16: =Full!F276 -> 0 | H16: =Full!G276 -> 0 | I16: =Full!F269 -> 5 | J16: =Full!G269 -> 70000 | K16: =I16 -> 5 | L16: =J16 -> 70000
A17: 8 | B17: Binderclips Joyko 111 | C17: =Full!F303 -> 1 | D17: =Full!G303 -> 7215 | E17: =Full!F304 -> 0 | F17: =Full!G304 -> 0 | G17: =Full!F312 -> 0 | H17: =Full!G312 -> 0 | I17: =Full!F305 -> 1 | J17: =Full!G305 -> 7215 | K17: =I17 -> 1 | L17: =J17 -> 7215
A18: 9 | B18: Binderclips Joyko 155 | C18: =Full!F340 -> 0 | D18: =Full!G340 -> 0 | E18: =Full!F341 -> 0 | F18: =Full!G341 -> 0 | G18: =Full!F349 -> 0 | H18: =Full!G349 -> 0 | I18: =Full!F342 -> 0 | J18: =Full!G342 -> 0 | K18: =I18 -> 0 | L18: =J18 -> 0
A19: 10 | B19: Ballpoint Tezo | C19: =Full!F386 -> 4 | D19: =Full!G386 -> 22000 | E19: =Full!F387 -> 0 | F19: =Full!G387 -> 0 | G19: =Full!F395 -> 0 | H19: =Full!G395 -> 0 | I19: =Full!F388 -> 4 | J19: =Full!G388 -> 22000 | K19: =I19 -> 4 | L19: =J19 -> 22000
A20: 11 | B20: Buku kwitansi ppl sedang | C20: =Full!F417 -> 0 | D20: =Full!G417 -> 0 | E20: =Full!F418 -> 0 | F20: =Full!G418 -> 0 | G20: =Full!F426 -> 0 | H20: =Full!G426 -> 0 | I20: =Full!F419 -> 0 | J20: =Full!G419 -> 0 | K20: =I20 -> 0 | L20: =J20 -> 0
A21: 12 | B21: Buku Ekpedisi | C21: =Full!F446 -> 0 | D21: =Full!G446 -> 0 | E21: =Full!F447 -> 0 | F21: =Full!G447 -> 0 | G21: =Full!F455 -> 0 | H21: =Full!G455 -> 0 | I21: =Full!F448 -> 0 | J21: =Full!G448 -> 0 | K21: =I21 -> 0 | L21: =J21 -> 0
A22: 13 | B22: Cutter L-500 | C22: =Full!F484 -> 0 | D22: =Full!G484 -> 0 | E22: =Full!F485 -> 0 | F22: =Full!G485 -> 0 | G22: =Full!F493 -> 0 | H22: =Full!G493 -> 0 | I22: =Full!F486 -> 0 | J22: =Full!G486 -> 0 | K22: =I22 -> 0 | L22: =J22 -> 0
A23: 14 | B23: Cutter A-300 | C23: =Full!F520 -> 0 | D23: =Full!G520 -> 0 | E23: =Full!F521 -> 0 | F23: =Full!G521 -> 0 | G23: =Full!F529 -> 0 | H23: =Full!G529 -> 0 | I23: =Full!F522 -> 0 | J23: =Full!G522 -> 0 | K23: =I23 -> 0 | L23: =J23 -> 0
A24: 15 | B24: Luxe 32 GB Type c | C24: =Full!F550 -> 0 | D24: =Full!G550 -> 0 | E24: =Full!F551 -> 0 | F24: =Full!G551 -> 0 | G24: =Full!F559 -> 0 | H24: =Full!G559 -> 0 | I24: =Full!F552 -> 0 | J24: =Full!G552 -> 0 | K24: =I24 -> 0 | L24: =J24 -> 0
A25: 16 | B25: Isi cuter L 150 | C25: =Full!F581 -> 4 | D25: =Full!G581 -> 31080 | E25: =Full!F582 -> 0 | F25: =Full!G582 -> 0 | G25: =Full!F590 -> 0 | H25: =Full!G590 -> 0 | I25: =Full!F583 -> 4 | J25: =Full!G583 -> 31080 | K25: =I25 -> 4 | L25: =J25 -> 31080
A26: 17 | B26: Kertas NCR Top | C26: =Full!F621 -> 3 | D26: =Full!G621 -> 225000 | E26: =Full!F622 -> 0 | F26: =Full!G622 -> 0 | G26: =Full!F630 -> 0 | H26: =Full!G630 -> 0 | I26: =Full!F623 -> 3 | J26: =Full!G623 -> 225000 | K26: =I26 -> 3 | L26: =J26 -> 225000
A27: 18 | B27: Kertas HVS 70 gsm F4 | C27: =Full!F677 -> 25 | D27: =Full!G677 -> 1665000 | E27: =Full!F678 -> 22 | F27: =Full!G678 -> 1211343 | G27: =Full!F686 -> 15 | H27: =Full!G686 -> 745143 | I27: =Full!F679 -> 32 | J27: =Full!G679 -> 2131200 | K27: =I27 -> 32 | L27: =J27 -> 2131200
A28: 19 | B28: Kertas HVS 70 gsm A3 | C28: =Full!F717 -> 1 | D28: =Full!G717 -> 100000 | E28: =Full!F718 -> 0 | F28: =Full!G718 -> 0 | G28: =Full!F726 -> 0 | H28: =Full!G726 -> 0 | I28: =Full!F719 -> 1 | J28: =Full!G719 -> 100000 | K28: =I28 -> 1 | L28: =J28 -> 100000
A29: 20 | B29: Kertas HVS 70 gsm A4 | C29: =Full!F773 -> 0 | D29: =Full!G773 -> 0 | E29: =Full!F774 -> 24 | F29: =Full!G774 -> 1348650 | G29: =Full!F782 -> 17 | H29: =Full!G782 -> 925185 | I29: =Full!F775 -> 7 | J29: =Full!G775 -> 423465 | K29: =I29 -> 7 | L29: =J29 -> 423465
A30: 21 | B30: Kertas NCR Continuous 4 ply | C30: =Full!F818 -> 0 | D30: =Full!G818 -> 0 | E30: =Full!F819 -> 0 | F30: =Full!G819 -> 0 | G30: =Full!F827 -> 0 | H30: =Full!G827 -> 0 | I30: =Full!F820 -> 0 | J30: =Full!G820 -> 0 | K30: =I30 -> 0 | L30: =J30 -> 0
A31: 22 | B31: Lem Povinal Cair 75 ml | C31: =Full!F859 -> 11 | D31: =Full!G859 -> 61050 | E31: =Full!F860 -> 0 | F31: =Full!G860 -> 0 | G31: =Full!F868 -> 0 | H31: =Full!G868 -> 0 | I31: =Full!F861 -> 11 | J31: =Full!G861 -> 61050 | K31: =I31 -> 11 | L31: =J31 -> 61050
A32: 23 | B32: Odner Bagus | C32: =Full!F896 -> 11 | D32: =Full!G896 -> 385000 | E32: =Full!F897 -> 0 | F32: =Full!G897 -> 0 | G32: =Full!F905 -> 0 | H32: =Full!G905 -> 0 | I32: =Full!F898 -> 11 | J32: =Full!G898 -> 385000 | K32: =I32 -> 11 | L32: =J32 -> 385000
A33: 24 | B33: Penanda File Post-it | C33: =Full!F946 -> 4 | D33: =Full!G946 -> 31080 | E33: =Full!F947 -> 0 | F33: =Full!G947 -> 0 | G33: =Full!F955 -> 0 | H33: =Full!G955 -> 0 | I33: =Full!F948 -> 4 | J33: =Full!G948 -> 31080 | K33: =I33 -> 4 | L33: =J33 -> 31080
A34: 25 | B34: Pita Printer LX-300
A35: 26 | B35: Paperclips no 5 | C35: =Full!F1027 -> 3 | D35: =Full!G1027 -> 21900 | E35: =Full!F1028 -> 0 | F35: =Full!G1028 -> 0 | G35: =Full!F1036 -> 0 | H35: =Full!G1036 -> 0 | I35: =Full!F1029 -> 3 | J35: =Full!G1029 -> 21900 | K35: =I35 -> 3 | L35: =J35 -> 21900
A36: 27 | B36: Paperclips no 3 | C36: =Full!F1075 -> 0 | D36: =Full!G1075 -> 0 | E36: =Full!F1076 -> 0 | F36: =Full!G1076 -> 0 | G36: =Full!F1084 -> 0 | H36: =Full!G1084 -> 0 | I36: =Full!F1077 -> 0 | J36: =Full!G1077 -> 0 | K36: =I36 -> 0 | L36: =J36 -> 0
A37: 28 | B37: Buku Kwarto/Peper line kecil 200 lbr | C37: =Full!F1113 -> 0 | D37: =Full!G1113 -> 0 | E37: =Full!F1114 -> 0 | F37: =Full!G1114 -> 0 | G37: =Full!F1122 -> 0 | H37: =Full!G1122 -> 0 | I37: =Full!F1115 -> 0 | J37: =Full!G1115 -> 0
A38: 29 | B38: Map plastik L | C38: =Full!F1151 -> 26 | D38: =Full!G1151 -> 481000 | E38: =Full!F1152 -> 0 | F38: =Full!G1152 -> 0 | G38: =Full!F1160 -> 0 | H38: =Full!G1160 -> 0 | I38: =Full!F1153 -> 26 | J38: =Full!G1153 -> 481000 | K38: =I38 -> 26 | L38: =J38 -> 481000
A39: 30 | B39: Buku doubl folio 200 lbr | C39: =Full!F1185 -> 0 | D39: =Full!G1185 -> 0 | E39: =Full!F1186 -> 0 | F39: =Full!G1186 -> 0 | G39: =Full!F1194 -> 0 | H39: =Full!G1194 -> 0 | I39: =Full!F1187 -> 0 | J39: =Full!G1187 -> 0 | K39: =I39 -> 0 | L39: =J39 -> 0
A40: 31 | B40: Stopmap Folio Tebal | C40: =Full!F1222 -> 0 | D40: =Full!G1222 -> 0 | E40: =Full!F1223 -> 0 | F40: =Full!G1223 -> 0 | G40: =Full!F1231 -> 0 | H40: =Full!G1231 -> 0 | I40: =Full!F1224 -> 0 | J40: =Full!G1224 -> 0 | K40: =I40 -> 0 | L40: =J40 -> 0
A41: 32 | B41: Stabillo Boss | C41: =Full!F1260 -> 12 | D41: =Full!G1260 -> 132000 | E41: =Full!F1261 -> 3 | F41: =Full!G1261 -> 26640 | G41: =Full!F1269 -> 6 | H41: =Full!G1269 -> 59640 | I41: =Full!F1262 -> 9 | J41: =Full!G1262 -> 99000 | K41: =I41 -> 9 | L41: =J41 -> 99000
A42: 33 | B42: Clean holder 60 F4 Bantek | C42: =Full!F1292 -> 0 | D42: =Full!G1292 -> 0 | E42: =Full!F1293 -> 0 | F42: =Full!G1293 -> 0 | G42: =Full!F1301 -> 0 | H42: =Full!G1301 -> 0 | I42: =Full!F1294 -> 0 | J42: =Full!G1294 -> 0 | K42: =I42 -> 0 | L42: =J42 -> 0
A43: 34 | B43: Tinta printer Epson black 70 ml | C43: =Full!F1327 -> 0 | D43: =Full!G1327 -> 0 | E43: =Full!F1328 -> 0 | F43: =Full!G1328 -> 0 | G43: =Full!F1336 -> 0 | H43: =Full!G1336 -> 0 | I43: =Full!F1329 -> 0 | J43: =Full!G1329 -> 0 | K43: =I43 -> 0 | L43: =J43 -> 0
...

Sheet Kertas
B1: Kartu Barang
A3: 1 | B3: Nama Barang : | C3: Amplop putih 90 | N3: ATK
B4: Satuan : | C4: box | N4: =N3 -> ATK
N5: =N4 -> ATK
B6: Tanggal | C6: Harga Pembelian per satuan | D6: Jumlah Barang | G6: Nilai Penerimaan Barang Persediaan | N6: =N5 -> ATK
D7: Masuk | E7: Keluar | F7: Sisa | N7: =N6 -> ATK
B8: 46024 | C8: 27750 | D8: 2 | F8: =D8-E8 -> 2 | G8: =C8*D8 -> 55500 | N8: =N7 -> ATK
G9: =C9*D9 -> 0 | N9: =N8 -> ATK
G10: =C10*D10 -> 0 | N10: =N9 -> ATK
G11: =C11*D11 -> 0 | N11: =N10 -> ATK
G12: =C12*D12 -> 0 | N12: =N11 -> ATK
G13: =C13*D13 -> 0 | N13: =N12 -> ATK
G14: =C14*D14 -> 0 | N14: =N13 -> ATK
G15: =C15*D15 -> 0 | N15: =N14 -> ATK
G16: =C16*D16 -> 0 | N16: =N15 -> ATK
G17: =C17*D17 -> 0 | N17: =N16 -> ATK
G18: =C18*D18 -> 0 | N18: =N17 -> ATK
G19: =C19*D19 -> 0 | N19: =N18 -> ATK
G20: =C20*D20 -> 0 | N20: =N19 -> ATK
... G25: =C25*D25 -> 0 | N25: =N24 -> ATK
N26: =N25 -> ATK
N27: =N26 -> ATK
N28: =N27 -> ATK
N29: =N28 -> ATK
N30: =N29 -> ATK
N31: =N30 -> ATK
H32: 0 | I32: sekretariat | N32: =N31 -> ATK
H33: 0 | I33: Upt rusunawa | N33: =N32 -> ATK
H34: 0 | I34: Bidang perumahan | N34: =N33 -> ATK
H35: 1 | I35: Bidang Permukiman | N35: =N34 -> ATK
B36: Jumlah | D36: =SUM(D8:D35) -> 2 | E36: =SUM(E8:E35) -> 0 | F36: =D36-E36 -> 2 | G36: =SUM(G8:G31) -> 55500 | H36: 0 | I36: upt makam | N36: =N35 -> ATK
N37: =N36 -> ATK
B38: Keterangan | F38: Jumlah | G38: Nilai | N38: =N37 -> ATK
B39: Saldo Awal 2 Jan 2026 | F39: =D8 -> 2 | G39: =G8 -> 55500 | N39: =N38 -> ATK
B40: Nilai Penerimaan Barang Persediaan Tahun 2026 | F40: =D36-F39 -> 0 | G40: =G36-G39 -> 0 | N40: =N39 -> ATK
B41: Saldo Akhir 31 Maret 2026 | F41: =SUM(B44:B47) -> 2 | G41: =SUM(D44:E47) -> 55500 | N41: =N40 -> ATK
B42: Rincian: Metode Penilaian FIFO | N42: =N41 -> ATK
B43: Jumlah Barang | C43: Harga Satuan | D43: Nilai | N43: =N42 -> ATK
B44: =F36 -> 2 | C44: 27750 | D44: =B44*C44 -> 55500 | N44: =N43 -> ATK
N45: =N44 -> ATK
...

Sheet April
A1: LAPORAN MUTASI BARANG PERSEDIAAN
A2: KERTAS DAN COVER
A3: DINAS PERUMAHAN RAKYAT DAN KAWASAN PERMUKIMAN
A5: No | B5: Rincian Nama Persediaan | C5: Saldo Per 1 April 2026 | E5: Penambahan | G5: Pengurangan | I5: Saldo Per 30 Apil 2026 | K5: Hasil Stock Opname | N5: Selisih | P5: Keterangan
C7: Jumlah | D7: Nilai Persediaan (Rp) | E7: =C7 -> Jumlah | F7: =D7 -> Nilai Persediaan (Rp) | G7: =E7 -> Jumlah | H7: =F7 -> Nilai Persediaan (Rp) | I7: =G7 -> Jumlah | J7: =H7 -> Nilai Persediaan (Rp) | K7: =I7 -> Jumlah | L7: =J7 -> Nilai Persediaan (Rp) | M7: *Kondisi | N7: Jumlah | O7: Nilai Persediaan (Rp)
A9: 1 | B9: 2 | C9: 3 | D9: 4 | E9: 5 | F9: 6 | G9: 7 | H9: 8 | I9: 9 (3+5-7) | J9: 10 (4+6-8) | K9: 11 | L9: 12 | M9: 13 | N9: 14 (9-11) | O9: 15 (10-12) | P9: 16
A10: 1 | B10: Kertas NCR Top | C10: =Kertas!F621 -> 3 | D10: =Kertas!G621 -> 225000 | E10: =Kertas!F622 -> 0 | F10: =Kertas!G622 -> 0 | G10: =Kertas!F630 -> 0 | H10: =Kertas!G630 -> 0 | I10: =Kertas!F623 -> 3 | J10: =Kertas!G623 -> 225000 | K10: =I10 -> 3 | L10: =J10 -> 225000
A11: 2 | B11: Kertas HVS 70 gsm F4 | C11: =Kertas!F677 -> 32 | D11: =Kertas!G677 -> 2131200 | E11: =Kertas!F678 -> 2 | F11: =Kertas!G678 -> 122100 | G11: =Kertas!F686 -> 7 | H11: =Kertas!G686 -> 455100 | I11: =Kertas!F679 -> 27 | J11: =Kertas!G679 -> 1798200 | K11: =I11 -> 27 | L11: =J11 -> 1798200
A12: 3 | B12: Kertas HVS 70 gsm A3 | C12: =Kertas!F717 -> 1 | D12: =Kertas!G717 -> 100000 | E12: =Kertas!F718 -> 0 | F12: =Kertas!G718 -> 0 | G12: =Kertas!F726 -> 0 | H12: =Kertas!G726 -> 0 | I12: =Kertas!F719 -> 1 | J12: =Kertas!G719 -> 100000 | K12: =I12 -> 1 | L12: =J12 -> 100000
A13: 4 | B13: Kertas HVS 70 gsm A4 | C13: =Kertas!F765 -> 7 | D13: =Kertas!G765 -> 396270 | E13: =Kertas!F766 -> 44 | F13: =Kertas!G766 -> 2490840 | G13: =Kertas!F774 -> 44 | H13: =Kertas!G774 -> 2490840 | I13: =Kertas!F767 -> 7 | J13: =Kertas!G767 -> 396270 | K13: =I13 -> 7 | L13: =J13 -> 396270
A14: 5 | B14: Kertas NCR Continuous 4 ply | C14: =Kertas!F810 -> 0 | D14: =Kertas!G810 -> 0 | E14: =Kertas!F811 -> 0 | F14: =Kertas!G811 -> 0 | G14: =Kertas!F819 -> 0 | H14: =Kertas!G819 -> 0 | I14: =Kertas!F812 -> 0 | J14: =Kertas!G812 -> 0 | K14: =I14 -> 0 | L14: =J14 -> 0
A15: 6 | B15: Kertas HVS 70 gsm F4 warna | C15: =Kertas!F2682 -> 8 | D15: =Kertas!G2682 -> 704000 | E15: =Kertas!F2683 -> 0 | F15: =Kertas!G2683 -> 0 | G15: =Kertas!F2691 -> 0 | H15: =Kertas!G2691 -> 0 | I15: =Kertas!F2684 -> 8 | J15: =Kertas!G2684 -> 704000 | K15: =I15 -> 8 | L15: =J15 -> 704000
A16: 7 | B16: Kertas NCR A4 | C16: =Kertas!F2779 -> 12 | D16: =Kertas!G2779 -> 432000 | E16: =Kertas!F2780 -> 0 | F16: =Kertas!G2780 -> 0 | G16: =Kertas!F2788 -> 3 | H16: =Kertas!G2788 -> 108000 | I16: =Kertas!F2781 -> 9 | J16: =Kertas!G2781 -> 324000 | K16: =I16 -> 9 | L16: =J16 -> 324000
A17: 8 | B17: Kertas foto/A4 | C17: =Kertas!F2871 -> 0 | D17: =Kertas!G2871 -> 0 | E17: =Kertas!F2872 -> 0 | F17: =Kertas!G2872 -> 0 | G17: =Kertas!F2880 -> 0 | H17: =Kertas!G2880 -> 0 | I17: =Kertas!F2873 -> 0 | J17: =Kertas!G2873 -> 0 | K17: =I17 -> 0 | L17: =J17 -> 0
A18: 9 | B18: kertas gaji | C18: =Kertas!F2901 -> 0 | D18: =Kertas!G2901 -> 0 | E18: =Kertas!F2902 -> 0 | F18: =O142855 -> 0 | G18: =Kertas!F2910 -> 0 | H18: =Kertas!G2910 -> 0 | I18: =Kertas!F2903 -> 0 | J18: =Kertas!G2903 -> 0 | K18: =I18 -> 0 | L18: =J18 -> 0
A19: 10 | B19: Kertas NCR Middle | C19: =Kertas!F3583 -> 3 | D19: =Kertas!G3583 -> 225000 | E19: =Kertas!F3584 -> 0 | F19: =Kertas!G3584 -> 0 | G19: =Kertas!F3592 -> 0 | H19: =Kertas!G3592 -> 0 | I19: =Kertas!F3585 -> 3 | J19: =Kertas!G3585 -> 225000 | K19: =I19 -> 3 | L19: =J19 -> 225000
A20: 11 | B20: Kertas NCR Botom | C20: =Kertas!F3627 -> 3 | D20: =Kertas!G3627 -> 225000 | E20: =Kertas!F3628 -> 0 | F20: =Kertas!G3628 -> 0 | G20: =Kertas!F3636 -> 0 | H20: =Kertas!G3636 -> 0 | I20: =Kertas!F3629 -> 3 | J20: =Kertas!G3629 -> 225000 | K20: =I20 -> 3 | L20: =J20 -> 225000
A21: 12 | B21: Kertas HVS 70 gsm A4 warna | C21: =Kertas!F3664 -> 2 | D21: =Kertas!G3664 -> 140000 | E21: =Kertas!F3665 -> 0 | F21: =Kertas!G3665 -> 0 | G21: =Kertas!F3673 -> 2 | H21: =Kertas!G3673 -> 140000 | I21: =Kertas!F3666 -> 0 | J21: =Kertas!G3666 -> 0 | K21: =I21 -> 0 | L21: =J21 -> 0
B23: Jumlah Alat Tulis Kantor | C23: =SUM(C10:C22) -> 71 | D23: =SUM(D10:D22) -> 4578470 | E23: =SUM(E10:E22) -> 46 | F23: =SUM(F10:F22) -> 2612940 | G23: =SUM(G10:G22) -> 56 | H23: =SUM(H10:H22) -> 3193940 | I23: =SUM(I10:I22) -> 61 | J23: =SUM(J10:J22) -> 3997470 | ... O23: =SUM(O10:O22) -> 0
M25: Pasuruan, 30 April 2026
C26: Yang Diperiksa, | N26: Pemeriksa,
C27: Pembantu Pengurus Barang Pengguna | N27: Pejabat Penatausahaan Barang Pengguna
C30: MUSTOFA | H30: Mengetahui | N30: IIL ROSIAWATI,ST
C31: NIP. 1972060820070111020 | H31: Kepala Dinas Perumahan rakyat Dan Kawasan Permukiman | N31: NIP. 197905202010012024
H34: AKUNG NOVAJANTO SODIQ NUCH,ST.MT
H35: NIP.197211257003121006

Sheet KB Mei
B1: Kartu Barang
A3: 1 | B3: Nama Barang : | C3: Amplop putih 90 | N3: ATK
B4: Satuan : | C4: box | N4: =N3 -> ATK
N5: =N4 -> ATK
B6: Tanggal | C6: Harga Pembelian per satuan | D6: Jumlah Barang | G6: Nilai Penerimaan Barang Persediaan | N6: =N5 -> ATK
D7: Masuk | E7: Keluar | F7: Sisa | N7: =N6 -> ATK
B8: 46024 | C8: 27750 | D8: 2 | F8: =D8-E8 -> 2 | G8: =C8*D8 -> 55500 | N8: =N7 -> ATK
G9: =C9*D9 -> 0 | N9: =N8 -> ATK
G10: =C10*D10 -> 0 | N10: =N9 -> ATK
G11: =C11*D11 -> 0 | N11: =N10 -> ATK
G12: =C12*D12 -> 0 | N12: =N11 -> ATK
G13: =C13*D13 -> 0 | N13: =N12 -> ATK
G14: =C14*D14 -> 0 | N14: =N13 -> ATK
G15: =C15*D15 -> 0 | N15: =N14 -> ATK
G16: =C16*D16 -> 0 | N16: =N15 -> ATK
G17: =C17*D17 -> 0 | N17: =N16 -> ATK
G18: =C18*D18 -> 0 | N18: =N17 -> ATK
G19: =C19*D19 -> 0 | N19: =N18 -> ATK
G20: =C20*D20 -> 0 | N20: =N19 -> ATK
... G25: =C25*D25 -> 0 | N25: =N24 -> ATK
N26: =N25 -> ATK
N27: =N26 -> ATK
N28: =N27 -> ATK
N29: =N28 -> ATK
N30: =N29 -> ATK
N31: =N30 -> ATK
H32: 0 | I32: sekretariat | N32: =N31 -> ATK
H33: 0 | I33: Upt rusunawa | N33: =N32 -> ATK
H34: 0 | I34: Bidang perumahan | N34: =N33 -> ATK
H35: 1 | I35: Bidang Permukiman | N35: =N34 -> ATK
B36: Jumlah | D36: =SUM(D8:D35) -> 2 | E36: =SUM(E8:E35) -> 0 | F36: =D36-E36 -> 2 | G36: =SUM(G8:G31) -> 55500 | H36: 0 | I36: upt makam | N36: =N35 -> ATK
N37: =N36 -> ATK
B38: Keterangan | F38: Jumlah | G38: Nilai | N38: =N37 -> ATK
B39: Saldo Awal 2 Jan 2026 | F39: =D8 -> 2 | G39: =G8 -> 55500 | N39: =N38 -> ATK
B40: Nilai Penerimaan Barang Persediaan Tahun 2026 | F40: =D36-F39 -> 0 | G40: =G36-G39 -> 0 | N40: =N39 -> ATK
B41: Saldo Akhir 31 Maret 2026 | F41: =SUM(B44:B47) -> 2 | G41: =SUM(D44:E47) -> 55500 | N41: =N40 -> ATK
B42: Rincian: Metode Penilaian FIFO | N42: =N41 -> ATK
B43: Jumlah Barang | C43: Harga Satuan | D43: Nilai | N43: =N42 -> ATK
B44: =F36 -> 2 | C44: 27750 | D44: =B44*C44 -> 55500 | N44: =N43 -> ATK
N45: =N44 -> ATK
...

Sheet Mei
A1: LAPORAN MUTASI BARANG PERSEDIAAN
A2: KERTAS DAN COVER
A3: DINAS PERUMAHAN RAKYAT DAN KAWASAN PERMUKIMAN
A5: No | B5: Rincian Nama Persediaan | C5: Saldo Per 1 Mei 2026 | E5: Penambahan | G5: Pengurangan | I5: Saldo Per 30 Mei 2026 | K5: Hasil Stock Opname | N5: Selisih | P5: Keterangan
C7: Jumlah | D7: Nilai Persediaan (Rp) | E7: =C7 -> Jumlah | F7: =D7 -> Nilai Persediaan (Rp) | G7: =E7 -> Jumlah | H7: =F7 -> Nilai Persediaan (Rp) | I7: =G7 -> Jumlah | J7: =H7 -> Nilai Persediaan (Rp) | K7: =I7 -> Jumlah | L7: =J7 -> Nilai Persediaan (Rp) | M7: *Kondisi | N7: Jumlah | O7: Nilai Persediaan (Rp)
A9: 1 | B9: 2 | C9: 3 | D9: 4 | E9: 5 | F9: 6 | G9: 7 | H9: 8 | I9: 9 (3+5-7) | J9: 10 (4+6-8) | K9: 11 | L9: 12 | M9: 13 | N9: 14 (9-11) | O9: 15 (10-12) | P9: 16
A10: 1 | B10: Kertas NCR Top | C10: ='KB Mei'!F621 -> 3 | D10: ='KB Mei'!G621 -> 225000 | E10: ='KB Mei'!F622 -> 2 | F10: ='KB Mei'!G622 -> 177600 | G10: ='KB Mei'!F630 -> 2 | H10: ='KB Mei'!G630 -> 177600 | I10: ='KB Mei'!F623 -> 3 | J10: ='KB Mei'!G623 -> 225000 | K10: =I10 -> 3 | L10: =J10 -> 225000
A11: 2 | B11: Kertas HVS 70 gsm F4 | C11: ='KB Mei'!F677 -> 27 | D11: ='KB Mei'!G677 -> 1798200 | E11: ='KB Mei'!F678 -> 67 | F11: ='KB Mei'!G678 -> 3272280 | G11: ='KB Mei'!F686 -> 11 | H11: ='KB Mei'!G686 -> 608280 | I11: ='KB Mei'!F679 -> 83 | J11: ='KB Mei'!G679 -> 4462200 | K11: =I11 -> 83 | L11: =J11 -> 4462200
A12: 3 | B12: Kertas HVS 70 gsm A3 | C12: ='KB Mei'!F717 -> 1 | D12: ='KB Mei'!G717 -> 100000 | E12: ='KB Mei'!F718 -> 0 | F12: ='KB Mei'!G718 -> 0 | G12: ='KB Mei'!F726 -> 0 | H12: ='KB Mei'!G726 -> 0 | I12: ='KB Mei'!F719 -> 1 | J12: ='KB Mei'!G719 -> 100000 | K12: =I12 -> 1 | L12: =J12 -> 100000
A13: 4 | B13: Kertas HVS 70 gsm A4 | C13: ='KB Mei'!F768 -> 7 | D13: ='KB Mei'!G768 -> 396270 | E13: ='KB Mei'!F769 -> 147 | F13: ='KB Mei'!G769 -> 7032960 | G13: ='KB Mei'!F777 -> 72 | H13: ='KB Mei'!G777 -> 3697410 | I13: ='KB Mei'!F770 -> 82 | J13: ='KB Mei'!G770 -> 3731820 | K13: =I13 -> 82 | L13: =J13 -> 3731820
A14: 5 | B14: Kertas NCR Continuous 4 ply | C14: ='KB Mei'!F813 -> 0 | D14: ='KB Mei'!G813 -> 0 | E14: ='KB Mei'!F814 -> 0 | F14: ='KB Mei'!G814 -> 0 | G14: ='KB Mei'!F822 -> 0 | H14: ='KB Mei'!G822 -> 0 | I14: ='KB Mei'!F815 -> 0 | J14: ='KB Mei'!G815 -> 0 | K14: =I14 -> 0 | L14: =J14 -> 0
A15: 6 | B15: Kertas HVS 70 gsm F4 warna | C15: ='KB Mei'!F2685 -> 8 | D15: ='KB Mei'!G2685 -> 704000 | E15: ='KB Mei'!F2686 -> 0 | F15: ='KB Mei'!G2686 -> 0 | G15: ='KB Mei'!F2694 -> 0 | H15: ='KB Mei'!G2694 -> 0 | I15: ='KB Mei'!F2687 -> 8 | J15: ='KB Mei'!G2687 -> 704000 | K15: =I15 -> 8 | L15: =J15 -> 704000
A16: 7 | B16: Kertas NCR A4 | C16: ='KB Mei'!F2782 -> 9 | D16: ='KB Mei'!G2782 -> 324000 | E16: ='KB Mei'!F2783 -> 52 | F16: ='KB Mei'!G2783 -> 4213560 | G16: ='KB Mei'!F2791 -> 55 | H16: ='KB Mei'!G2791 -> 4321560 | I16: ='KB Mei'!F2784 -> 6 | J16: ='KB Mei'!G2784 -> 216000 | K16: =I16 -> 6 | L16: =J16 -> 216000
A17: 8 | B17: Kertas foto/A4 | C17: ='KB Mei'!F2874 -> 0 | D17: ='KB Mei'!G2874 -> 0 | E17: ='KB Mei'!F2875 -> 0 | F17: ='KB Mei'!G2875 -> 0 | G17: ='KB Mei'!F2883 -> 0 | H17: ='KB Mei'!G2883 -> 0 | I17: ='KB Mei'!F2876 -> 0 | J17: ='KB Mei'!G2876 -> 0 | K17: =I17 -> 0 | L17: =J17 -> 0
A18: 9 | B18: kertas gaji | C18: ='KB Mei'!F2904 -> 0 | D18: ='KB Mei'!G2904 -> 0 | E18: ='KB Mei'!F2905 -> 0 | F18: =O142855 -> 0 | G18: ='KB Mei'!F2913 -> 0 | H18: ='KB Mei'!G2913 -> 0 | I18: ='KB Mei'!F2906 -> 0 | J18: ='KB Mei'!G2906 -> 0 | K18: =I18 -> 0 | L18: =J18 -> 0
A19: 10 | B19: Kertas NCR Middle | C19: ='KB Mei'!F3586 -> 3 | D19: ='KB Mei'!G3586 -> 225000 | E19: ='KB Mei'!F3587 -> 2 | F19: ='KB Mei'!G3587 -> 155999.84 | G19: ='KB Mei'!F3595 -> 2 | H19: ='KB Mei'!G3595 -> 155999.84 | I19: ='KB Mei'!F3588 -> 3 | J19: ='KB Mei'!G3588 -> 225000 | K19: =I19 -> 3 | L19: =J19 -> 225000
A20: 11 | B20: Kertas NCR Botom | C20: ='KB Mei'!F3630 -> 3 | D20: ='KB Mei'!G3630 -> 225000 | E20: ='KB Mei'!F3631 -> 2 | F20: ='KB Mei'!G3631 -> 159999.16 | G20: ='KB Mei'!F3639 -> 2 | H20: ='KB Mei'!G3639 -> 159999.16 | I20: ='KB Mei'!F3632 -> 3 | J20: ='KB Mei'!G3632 -> 225000 | K20: =I20 -> 3 | L20: =J20 -> 225000
A21: 12 | B21: Kertas HVS 70 gsm A4 warna | C21: ='KB Mei'!F3667 -> 0 | D21: ='KB Mei'!G3667 -> 0 | E21: ='KB Mei'!F3668 -> 0 | F21: ='KB Mei'!G3668 -> 0 | G21: ='KB Mei'!F3676 -> 0 | H21: ='KB Mei'!G3676 -> 0 | I21: ='KB Mei'!F3669 -> 0 | J21: ='KB Mei'!G3669 -> 0 | K21: =I21 -> 0 | L21: =J21 -> 0
B23: Jumlah Alat Tulis Kantor | C23: =SUM(C10:C22) -> 61 | D23: =SUM(D10:D22) -> 3997470 | E23: =SUM(E10:E22) -> 272 | F23: =SUM(F10:F22) -> 15012399 | G23: =SUM(G10:G22) -> 144 | H23: =SUM(H10:H22) -> 9120849 | I23: =SUM(I10:I22) -> 189 | J23: =SUM(J10:J22) -> 9889020 | ... O23: =SUM(O10:O22) -> 0
M25: Pasuruan, 30 mei 2026
C26: Yang Diperiksa, | N26: Pemeriksa,
C27: Pembantu Pengurus Barang Pengguna | N27: Pejabat Penatausahaan Barang Pengguna
C30: MUSTOFA | H30: Mengetahui | N30: IIL ROSIAWATI,ST
C31: NIP. 1972060820070111020 | H31: Kepala Dinas Perumahan rakyat Dan Kawasan Permukiman | N31: NIP. 197905202010012024
H34: AKUNG NOVAJANTO SODIQ NUCH,ST.MT
H35: NIP.197211257003121006

Sheet KB Juni
B1: Kartu Barang
A3: 1 | B3: Nama Barang : | C3: Amplop putih 90 | N3: ATK
B4: Satuan : | C4: box | N4: =N3 -> ATK
N5: =N4 -> ATK
B6: Tanggal | C6: Harga Pembelian per satuan | D6: Jumlah Barang | G6: Nilai Penerimaan Barang Persediaan | N6: =N5 -> ATK
D7: Masuk | E7: Keluar | F7: Sisa | N7: =N6 -> ATK
B8: 46024 | C8: 27750 | D8: 2 | F8: =D8-E8 -> 2 | G8: =C8*D8 -> 55500 | N8: =N7 -> ATK
G9: =C9*D9 -> 0 | N9: =N8 -> ATK
G10: =C10*D10 -> 0 | N10: =N9 -> ATK
G11: =C11*D11 -> 0 | N11: =N10 -> ATK
G12: =C12*D12 -> 0 | N12: =N11 -> ATK
G13: =C13*D13 -> 0 | N13: =N12 -> ATK
G14: =C14*D14 -> 0 | N14: =N13 -> ATK
G15: =C15*D15 -> 0 | N15: =N14 -> ATK
G16: =C16*D16 -> 0 | N16: =N15 -> ATK
G17: =C17*D17 -> 0 | N17: =N16 -> ATK
G18: =C18*D18 -> 0 | N18: =N17 -> ATK
G19: =C19*D19 -> 0 | N19: =N18 -> ATK
G20: =C20*D20 -> 0 | N20: =N19 -> ATK
... G25: =C25*D25 -> 0 | N25: =N24 -> ATK
N26: =N25 -> ATK
N27: =N26 -> ATK
N28: =N27 -> ATK
N29: =N28 -> ATK
N30: =N29 -> ATK
N31: =N30 -> ATK
H32: 0 | I32: sekretariat | N32: =N31 -> ATK
H33: 0 | I33: Upt rusunawa | N33: =N32 -> ATK
H34: 0 | I34: Bidang perumahan | N34: =N33 -> ATK
H35: 1 | I35: Bidang Permukiman | N35: =N34 -> ATK
B36: Jumlah | D36: =SUM(D8:D35) -> 2 | E36: =SUM(E8:E35) -> 0 | F36: =D36-E36 -> 2 | G36: =SUM(G8:G31) -> 55500 | H36: 0 | I36: upt makam | N36: =N35 -> ATK
N37: =N36 -> ATK
B38: Keterangan | F38: Jumlah | G38: Nilai | N38: =N37 -> ATK
B39: Saldo Awal 2 Jan 2026 | F39: =D8 -> 2 | G39: =G8 -> 55500 | N39: =N38 -> ATK
B40: Nilai Penerimaan Barang Persediaan Tahun 2026 | F40: =D36-F39 -> 0 | G40: =G36-G39 -> 0 | N40: =N39 -> ATK
B41: Saldo Akhir 31 Maret 2026 | F41: =SUM(B44:B47) -> 2 | G41: =SUM(D44:E47) -> 55500 | N41: =N40 -> ATK
B42: Rincian: Metode Penilaian FIFO | N42: =N41 -> ATK
B43: Jumlah Barang | C43: Harga Satuan | D43: Nilai | N43: =N42 -> ATK
B44: =F36 -> 2 | C44: 27750 | D44: =B44*C44 -> 55500 | N44: =N43 -> ATK
N45: =N44 -> ATK
...

Sheet Juni
A1: LAPORAN MUTASI BARANG PERSEDIAAN
A2: KERTAS DAN COVER
A3: DINAS PERUMAHAN RAKYAT DAN KAWASAN PERMUKIMAN
A5: No | B5: Rincian Nama Persediaan | C5: Saldo Per 1 Juni 2026 | E5: Penambahan | G5: Pengurangan | I5: Saldo Per 30 Juni 2026 | K5: Hasil Stock Opname | N5: Selisih | P5: Keterangan
C7: Jumlah | D7: Nilai Persediaan (Rp) | E7: =C7 -> Jumlah | F7: =D7 -> Nilai Persediaan (Rp) | G7: =E7 -> Jumlah | H7: =F7 -> Nilai Persediaan (Rp) | I7: =G7 -> Jumlah | J7: =H7 -> Nilai Persediaan (Rp) | K7: =I7 -> Jumlah | L7: =J7 -> Nilai Persediaan (Rp) | M7: *Kondisi | N7: Jumlah | O7: Nilai Persediaan (Rp)
A9: 1 | B9: 2 | C9: 3 | D9: 4 | E9: 5 | F9: 6 | G9: 7 | H9: 8 | I9: 9 (3+5-7) | J9: 10 (4+6-8) | K9: 11 | L9: 12 | M9: 13 | N9: 14 (9-11) | O9: 15 (10-12) | P9: 16
A10: 1 | B10: Kertas NCR Top | C10: ='KB Juni'!F621 -> 3 | D10: ='KB Juni'!G621 -> 225000 | E10: ='KB Juni'!F622 -> 0 | F10: ='KB Juni'!G622 -> 0 | G10: ='KB Juni'!F630 -> 0 | H10: ='KB Juni'!G630 -> 0 | I10: ='KB Juni'!F623 -> 3 | J10: ='KB Juni'!G623 -> 225000 | K10: =I10 -> 3 | L10: =J10 -> 225000
A11: 2 | B11: Kertas HVS 70 gsm F4 | C11: ='KB Juni'!F677 -> 83 | D11: ='KB Juni'!G677 -> 4462200 | E11: ='KB Juni'!F678 -> 0 | F11: ='KB Juni'!G678 -> 0 | G11: ='KB Juni'!F686 -> 4 | H11: ='KB Juni'!G686 -> 266400 | I11: ='KB Juni'!F679 -> 79 | J11: ='KB Juni'!G679 -> 4195800 | K11: =I11 -> 79 | L11: =J11 -> 4195800
A12: 3 | B12: Kertas HVS 70 gsm A3 | C12: ='KB Juni'!F717 -> 1 | D12: ='KB Juni'!G717 -> 100000 | E12: ='KB Juni'!F718 -> 0 | F12: ='KB Juni'!G718 -> 0 | G12: ='KB Juni'!F726 -> 0 | H12: ='KB Juni'!G726 -> 0 | I12: ='KB Juni'!F719 -> 1 | J12: ='KB Juni'!G719 -> 100000 | K12: =I12 -> 1 | L12: =J12 -> 100000
A13: 4 | B13: Kertas HVS 70 gsm A4 | C13: ='KB Juni'!F768 -> 82 | D13: ='KB Juni'!G768 -> 3731820 | E13: ='KB Juni'!F769 -> 29 | F13: ='KB Juni'!G769 -> 1319790 | G13: ='KB Juni'!F777 -> 26 | H13: ='KB Juni'!G777 -> 1183260 | I13: ='KB Juni'!F770 -> 85 | J13: ='KB Juni'!G770 -> 3868350 | K13: =I13 -> 85 | L13: =J13 -> 3868350
A14: 5 | B14: Kertas NCR Continuous 4 ply | C14: ='KB Juni'!F813 -> 0 | D14: ='KB Juni'!G813 -> 0 | E14: ='KB Juni'!F814 -> 43 | F14: ='KB Juni'!G814 -> 3102450 | G14: ='KB Juni'!F822 -> 43 | H14: ='KB Juni'!G822 -> 3102450 | I14: ='KB Juni'!F815 -> 0 | J14: ='KB Juni'!G815 -> 0 | K14: =I14 -> 0 | L14: =J14 -> 0
A15: 6 | B15: Kertas HVS 70 gsm F4 warna | C15: ='KB Juni'!F2685 -> 8 | D15: ='KB Juni'!G2685 -> 704000 | E15: ='KB Juni'!F2686 -> 0 | F15: ='KB Juni'!G2686 -> 0 | G15: ='KB Juni'!F2694 -> 0 | H15: ='KB Juni'!G2694 -> 0 | I15: ='KB Juni'!F2687 -> 8 | J15: ='KB Juni'!G2687 -> 704000 | K15: =I15 -> 8 | L15: =J15 -> 704000
A16: 7 | B16: Kertas NCR A4 | C16: ='KB Juni'!F2782 -> 6 | D16: ='KB Juni'!G2782 -> 216000 | E16: ='KB Juni'!F2783 -> 0 | F16: ='KB Juni'!G2783 -> 0 | G16: ='KB Juni'!F2791 -> 0 | H16: ='KB Juni'!G2791 -> 0 | I16: ='KB Juni'!F2784 -> 6 | J16: ='KB Juni'!G2784 -> 216000 | K16: =I16 -> 6 | L16: =J16 -> 216000
A17: 8 | B17: Kertas foto/A4 | C17: ='KB Juni'!F2874 -> 0 | D17: ='KB Juni'!G2874 -> 0 | E17: ='KB Juni'!F2875 -> 0 | F17: ='KB Juni'!G2875 -> 0 | G17: ='KB Juni'!F2883 -> 0 | H17: ='KB Juni'!G2883 -> 0 | I17: ='KB Juni'!F2876 -> 0 | J17: ='KB Juni'!G2876 -> 0 | K17: =I17 -> 0 | L17: =J17 -> 0
A18: 9 | B18: kertas gaji | C18: ='KB Juni'!F2904 -> 0 | D18: ='KB Juni'!G2904 -> 0 | E18: ='KB Juni'!F2905 -> 0 | F18: =O142855 -> 0 | G18: ='KB Juni'!F2913 -> 0 | H18: ='KB Juni'!G2913 -> 0 | I18: ='KB Juni'!F2906 -> 0 | J18: ='KB Juni'!G2906 -> 0 | K18: =I18 -> 0 | L18: =J18 -> 0
A19: 10 | B19: Kertas NCR Middle | C19: ='KB Juni'!F3586 -> 3 | D19: ='KB Juni'!G3586 -> 225000 | E19: ='KB Juni'!F3587 -> 0 | F19: ='KB Juni'!G3587 -> 0 | G19: ='KB Juni'!F3595 -> 0 | H19: ='KB Juni'!G3595 -> 0 | I19: ='KB Juni'!F3588 -> 3 | J19: ='KB Juni'!G3588 -> 225000 | K19: =I19 -> 3 | L19: =J19 -> 225000
A20: 11 | B20: Kertas NCR Botom | C20: ='KB Juni'!F3630 -> 3 | D20: ='KB Juni'!G3630 -> 225000 | E20: ='KB Juni'!F3631 -> 0 | F20: ='KB Juni'!G3631 -> 0 | G20: ='KB Juni'!F3639 -> 0 | H20: ='KB Juni'!G3639 -> 0 | I20: ='KB Juni'!F3632 -> 3 | J20: ='KB Juni'!G3632 -> 225000 | K20: =I20 -> 3 | L20: =J20 -> 225000
A21: 12 | B21: Kertas HVS 70 gsm A4 warna | C21: ='KB Juni'!F3667 -> 0 | D21: ='KB Juni'!G3667 -> 0 | E21: ='KB Juni'!F3668 -> 0 | F21: ='KB Juni'!G3668 -> 0 | G21: ='KB Juni'!F3676 -> 0 | H21: ='KB Juni'!G3676 -> 0 | I21: ='KB Juni'!F3669 -> 0 | J21: ='KB Juni'!G3669 -> 0 | K21: =I21 -> 0 | L21: =J21 -> 0
B23: Jumlah Alat Tulis Kantor | C23: =SUM(C10:C22) -> 189 | D23: =SUM(D10:D22) -> 9889020 | E23: =SUM(E10:E22) -> 72 | F23: =SUM(F10:F22) -> 4422240 | G23: =SUM(G10:G22) -> 73 | H23: =SUM(H10:H22) -> 4552110 | I23: =SUM(I10:I22) -> 188 | J23: =SUM(J10:J22) -> 9759150 | ... O23: =SUM(O10:O22) -> 0
M25: Pasuruan, 30 Juni 2026
C26: Yang Diperiksa, | N26: Pemeriksa,
C27: Pembantu Pengurus Barang Pengguna | N27: Pejabat Penatausahaan Barang Pengguna
C30: MUSTOFA | H30: Mengetahui | N30: IIL ROSIAWATI,ST
C31: NIP. 1972060820070111020 | H31: Kepala Dinas Perumahan rakyat Dan Kawasan Permukiman | N31: NIP. 197905202010012024
H34: AKUNG NOVAJANTO SODIQ NUCH,ST.MT
H35: NIP.197211257003121006

Sheet stoc
A2: No | B2: Rincian Nama Persediaan | C2: Satuan | D2: Jumlah | E2: Harga Satuan | F2: Nilai Persediaan (Rp)
A3: 1 | B3: 2 | D3: 3 | E3: 4 | F3: 5
A4: I | B4: ALAT/BAHAN KEGIATAN KANTOR -ALAT TULIS KANTOR | F4: =F5+F52+F63 -> 16797285
B5: ALAT TULIS KANTOR | F5: =SUM(F6:F51) -> 7760960 | H5: 7781000 | I5: =H5-F5 -> 20040
A6: 1 | B6: Amplop putih 90 | C6: box | D6: =Full!B44 -> 2 | E6: =Full!C44 -> 27750 | F6: =D6*E6 -> 55500
A7: 2 | B7: Amplop putih 104 | C7: box | D7: =Full!B88 -> 9 | E7: =Full!C88 -> 21800 | F7: =D7*E7 -> 196200
A8: 3 | B8: Binderclips Joyko 260 | C8: pak | D8: =Full!B129 -> 7 | E8: =Full!C129 -> 22755 | F8: =D8*E8 -> 159285
A9: 4 | B9: Binder Clips 107 | C9: pak | D9: =Full!B231 -> 3 | E9: =Full!C231 -> 11500 | F9: =D9*E9 -> 34500
A10: 5 | B10: Binderclips 200 | C10: pak | D10: =Full!B272 -> 5 | E10: =Full!C272 -> 14000 | F10: =D10*E10 -> 70000
A11: 6 | B11: Binderclips Joyko 111 | C11: pak | D11: =Full!B308 -> 1 | E11: =Full!C308 -> 7215 | F11: =D11*E11 -> 7215
A12: 7 | B12: Binderclips Joyko 155 | C12: pak | D12: =Full!B345 -> 0 | E12: =Full!C345 -> 18500 | F12: =D12*E12 -> 0
A13: 8 | B13: Ballpoint Tezo | C13: pak | D13: =Full!B391 -> 4 | E13: =Full!C391 -> 5500 | F13: =D13*E13 -> 22000
A14: 10 | B14: Odner bagus | C14: buah | D14: =Full!B901 -> 11 | E14: =Full!C901 -> 35000 | F14: =D14*E14 -> 385000
A15: 11 | B15: Penanda File Post-it | C15: pak | D15: =Full!B951 -> 4 | E15: =Full!C951 -> 7770 | F15: =D15*E15 -> 31080
A16: 12 | B16: Paperclip no 5 | C16: pak | D16: =Full!B1032 -> 3 | E16: =Full!C1032 -> 7300 | F16: =D16*E16 -> 21900
A17: 14 | B17: Trigonal clip no 3 | C17: pak | D17: =Full!B1080 -> 0 | E17: =Full!C1080 -> 10500 | F17: =D17*E17 -> 0
A18: 15 | B18: Stabillo Boss | C18: buah | D18: =Full!B1265 -> 9 | E18: =Full!C1265 -> 11000 | F18: =D18*E18 -> 99000
A19: 16 | B19: Clin holder 60 F4 Bantek | C19: buah | D19: =Full!B1297 -> 0 | E19: =Full!C1297 -> 98000 | F19: =D19*E19 -> 0
B20: Seples MaX HD -10 | C20: buah | D20: =Full!B1440 -> 2 | E20: =Full!C1440 -> 35520 | F20: =D20*E20 -> 71040
A21: 17 | B21: Spidol snoowman Boardmarker | C21: buah | D21: =Full!B1475 -> 5 | E21: =Full!C1475 -> 11000 | F21: =D21*E21 -> 55000
A22: 18 | B22: Spidol Boardmarker permanen | C22: buah | D22: =Full!B1512 -> 3 | E22: =Full!C1512 -> 10000 | F22: =D22*E22 -> 30000
A23: 19 | B23: Plakband hitam | C23: buah | D23: 3 | E23: 16000 | F23: =D23*E23 -> 48000
A24: 20 | B24: Penggaris besi big | C24: buah | D24: 1 | E24: 12500 | F24: =D24*E24 -> 12500
A25: 21 | B25: Dokumen keeper resleting | C25: buah | D25: 6 | E25: 94000 | F25: =D25*E25 -> 564000
A26: 22 | B26: Bolpoint Gel | C26: buah | D26: =Full!B1655 -> 1 | E26: =Full!C1655 -> 5000 | F26: =D26*E26 -> 5000
A27: 23 | B27: Mab bisnis file | C27: buah | D27: 150 | E27: 7000 | F27: =D27*E27 -> 1050000
A28: 24 | B28: Isi Staples MAX 10 | C28: doz | D28: 5 | E28: 40000 | F28: =D28*E28 -> 200000
A29: 25 | B29: Tiep Ex kertas ct-522 | C29: buah | D29: 6 | E29: 8000 | F29: =D29*E29 -> 48000
A30: 26 | B30: Dokumen keeper isi 60 | C30: buah | D30: =Full!B1849 -> 4 | E30: =Full!C1849 -> 93000 | F30: =D30*E30 -> 372000
A31: 27 | B31: Lem stik besar | C31: buah | D31: 2 | E31: 14000 | F31: =D31*E31 -> 28000
A32: 28 | B32: isi Staples Max HD-10 | C32: pak | D32: =Full!B2069 -> 5 | E32: =Full!C2069 -> 3500 | F32: =D32*E32 -> 17500
A33: 29 | B33: Isi Steples besar HD 03 | C33: pak | D33: =Full!B2165 -> 11 | E33: =Full!C2165 -> 6500 | F33: =D33*E33 -> 71500
A34: 30 | B34: Isi Steples besar 9/16 | C34: pak | D34: =Full!B2194 -> 4 | E34: =Full!C2194 -> 3100 | F34: =D34*E34 -> 12400
A35: 31 | B35: Plak band putih | C35: buah | D35: =Full!B2426 -> 5 | E35: =Full!C2426 -> 99900 | F35: =D35*E35 -> 499500
A36: 32 | B36: Ballpoint Bp 388 | C36: buah | D36: 33 | E36: 2500 | F36: =D36*E36 -> 82500
A37: 33 | B37: Pensil 2B | C37: buah | D37: =Full!B2629 -> 31 | E37: =Full!C2629 -> 4440 | F37: =D37*E37 -> 137640
A38: 34 | B38: Buku tulis 38 | C38: buah | D38: =Full!B2824 -> 10 | E38: =Full!C2824 -> 5550 | F38: =D38*E38 -> 55500
A39: 35 | B39: Portepel | C39: buah | D39: =Full!B2949 -> 45 | E39: =Full!C2949 -> 9100 | F39: =D39*E39 -> 409500
A40: 36 | B40: Map gantung folio | C40: buah | D40: 100 | E40: 6000 | F40: =D40*E40 -> 600000
A41: 37 | B41: Isolasi besar bening | C41: buah | D41: =Full!B3205 -> 11 | E41: =Full!C3205 -> 13900 | F41: =D41*E41 -> 152900
...

Sheet Sheet1
A10: 1. Belanja alat/Bahan untuk kegiatan kantor ATK
A11: No | B11: Unit | C11: Jumlah Harga
A12: 1 | B12: Sekretariat | C12: 8415714
A13: 2 | B13: Bidang Permukiman | C13: 0
A14: 3 | B14: Bidang Perumahan | C14: 0
A15: 4 | B15: Upt Pemakaman | C15: 0
A16: 4 | B16: Upt Rusunawa | C16: 0
A17: Jumlah | C17: =SUM(C12:C16) -> 8415714
A19: 2. Belanja alat/Bahan untuk kegiatan kantor Kertas dan Cover
A20: No | B20: Unit | C20: Jumlah Harga
A21: 1 | B21: Sekretariat | C21: 3716000
A22: 2 | B22: Bidang Permukiman | C22: 0
A23: 3 | B23: Bidang Perumahan | C23: 0
A24: 4 | B24: Upt Pemakaman | C24: 0
A25: 4 | B25: Upt Rusunawa | C25: 0
A26: Jumlah | C26: =SUM(C21:C25) -> 3716000
A28: 3. Belanja alat/Bahan untuk kegiatan kantor Bahan Cetak
A29: No | B29: Unit | C29: Jumlah Harga
A30: 1 | B30: Sekretariat | C30: 5820740.8
A31: 2 | B31: Bidang Permukiman | C31: 0
A32: 3 | B32: Bidang Perumahan | C32: 0
A33: 4 | B33: Upt Pemakaman
A34: 4 | B34: Upt Rusunawa | C34: 0
A35: Jumlah | C35: =SUM(C30:C34) -> 5820740.8
A37: 4. Belanja alat/Bahan untuk kegiatan kantor Bahan Komputer
A38: No | B38: Unit | C38: Jumlah Harga
A39: 1 | B39: Sekretariat | C39: 7427890
A40: 2 | B40: Bidang Permukiman | C40: 0
A41: 3 | B41: Bidang Perumahan | C41: 0
A42: 4 | B42: Upt Pemakaman
A43: 4 | B43: Upt Rusunawa | C43: 0
A44: Jumlah | C44: =SUM(C39:C43) -> 7427890
A46: 5. Belanja alat/Bahan untuk kegiatan kantor Benda Pos
A47: No | B47: Unit | C47: Jumlah Harga
A48: 1 | B48: Sekretariat | C48: 200000
A49: 2 | B49: Bidang Permukiman | C49: 0
A50: 3 | B50: Bidang Perumahan | C50: 0
A51: 4 | B51: Upt Pemakaman
A52: 4 | B52: Upt Rusunawa | C52: 0
A53: Jumlah | C53: =SUM(C48:C52) -> 200000
...

Sheet Rekap Ade Rumus
B2: Amplop putih 90 | C2: ATK
B3: Amplop putih 104 | C3: ATK
B4: Binderclips Joyko 260 | C4: ATK
B5: Binder Clips 107 | C5: ATK
B6: Binderclips 200 | C6: ATK
B7: Binderclips Joyko 111 | C7: ATK
B8: Binderclips Joyko 155 | C8: ATK
B9: Ballpoint Tezo | C9: ATK
B10: Kwitansi kecil | C10: ATK
B11: Kwitansi tanggung | C11: ATK
B12: Cutter L-500 | C12: ATK
B13: Cutter A-300 | C13: ATK
... B91: Kertas HVS 70 gsm A4 warna | C91: Kertas
B92: ='Rekap Master'!B106 -> Hang map | C92: Komputer
B93: Pita Printer LX-300 | C93: Komputer
B94: Tinta printer Epson black 70 ml | C94: Komputer
B95: Tinta printer Epson warna | C95: Komputer
B96: Tinta printer 664 hitam | C96: Komputer
B97: Tinta printer 664 warna | C97: Komputer
B98: Flashdisk 16 Gb | C98: Komputer
B99: Tinta Epson 003 color | C99: Komputer
B100: Tinta Epson 003 black | C100: Komputer
B101: pita printer Lq-2190 | C101: Komputer
B102: Tinta Stempel | C102: Komputer
B103: Tinta HP GT52 warna | C103: Komputer
B104: Tinta HP GT53 | C104: Komputer
... B106: Mouse wireies | C106: Komputer
